Workbook

Sheet 표지
L3: 문서보안 | M3: 일반문서 / 대외비
B9: 프로젝트 일정계획표 (WBS)
B10: 판로플랫폼 고도화 및 유지관리
H18: 기업 로고 추가
A22: Copyright © 2026 by 한국사회적기업진흥원 한국사회적기업진흥원의 사전 승인 없이 본 내용의 전부 또는 일부에 대한 복사, 전재, 배포, 사용을 금합니다.

Sheet 개정이력
B2: 개정이력
B4: 버전 | C4: 날짜 | D4: 개정내용 | E4: 작성자 | F4: 승인자
B6: 0.1 | C6: 26.1.26 | D6: 최초 작성 | E6: 장일훈 | F6: 장일훈
B7: 0.2
B8: 0.3
B9: 0.4
B10: 0.5
B11: 0.6
B12: 0.7

Sheet 월간투입인력현황표
B2: 판로플랫폼 고도화 및 유지관리 - 월별 인력투입현황
B4: 기술자명 | C4: 업무 | D4: 기술등급 | E4: 회사 | F4: 투입공수 (목표) | G4: 투입공수 (누적) | H4: 잔여공수 | I4: 월별 인력투입현황
I5: 1월 | K5: 2월 | M5: 3월 | O5: 4월 | Q5: 5월 | S5: 6월 | U5: 7월 | W5: 8월 | Y5: 9월 | AA5: 10월 | AC5: 11월 | AE5: 12월
I6: 목표 | J6: 투입 | K6: 목표 | L6: 투입 | M6: 목표 | N6: 투입 | O6: 목표 | P6: 투입 | Q6: 목표 | R6: 투입 | S6: 목표 | T6: 투입 | U6: 목표 | V6: 투입 | W6: 목표 | X6: 투입 | Y6: 목표 | Z6: 투입 | AA6: 목표 | AB6: 투입 | AC6: 목표 | AD6: 투입 | AE6: 목표 | AF6: 투입
B7: 장일훈 | C7: PM | D7: 특급 | E7: ㈜이포넷 | F7: =SUM(I7,K7,M7,O7,Q7,S7,U7,W7,Y7,AA7,AC7,AE7) -> 11.2 | G7: =SUM(J7,L7,N7,P7,R7,T7,V7,X7,Z7,AB7,AD7,AF7) -> 2.2 | H7: =F7-G7 -> 9 | I7: 0.2 | J7: 0.2 | K7: 1 | L7: 1 | M7: 1 | N7: 1 | O7: 1 | Q7: 1 | S7: 1 | U7: 1 | W7: 1 | Y7: 1 | AA7: 1 | AC7: 1 | AE7: 1
B8: 김선형 | C8: 업무총괄PL | D8: 특급 | E8: ㈜이포넷 | F8: =SUM(I8,K8,M8,O8,Q8,S8,U8,W8,Y8,AA8,AC8,AE8) -> 11.2 | G8: =SUM(J8,L8,N8,P8,R8,T8,V8,X8,Z8,AB8,AD8,AF8) -> 2.2 | H8: =F8-G8 -> 9 | I8: 0.2 | J8: 0.2 | K8: 1 | L8: 1 | M8: 1 | N8: 1 | O8: 1 | Q8: 1 | S8: 1 | U8: 1 | W8: 1 | Y8: 1 | AA8: 1 | AC8: 1 | AE8: 1
B9: 송현주 | C9: 사업관리 | D9: 특급 | E9: ㈜이포넷 | F9: =SUM(I9,K9,M9,O9,Q9,S9,U9,W9,Y9,AA9,AC9,AE9) -> 11.2 | G9: =SUM(J9,L9,N9,P9,R9,T9,V9,X9,Z9,AB9,AD9,AF9) -> 2.2 | H9: =F9-G9 -> 9 | I9: 0.2 | J9: 0.2 | K9: 1 | L9: 1 | M9: 1 | N9: 1 | O9: 1 | Q9: 1 | S9: 1 | U9: 1 | W9: 1 | Y9: 1 | AA9: 1 | AC9: 1 | AE9: 1
B10: 황안나 | C10: 분석설계 | D10: 특급 | E10: ㈜이포넷 | F10: =SUM(I10,K10,M10,O10,Q10,S10,U10,W10,Y10,AA10,AC10,AE10) -> 11.2 | G10: =SUM(J10,L10,N10,P10,R10,T10,V10,X10,Z10,AB10,AD10,AF10) -> 2.2 | H10: =F10-G10 -> 9 | I10: 0.2 | J10: 0.2 | K10: 1 | L10: 1 | M10: 1 | N10: 1 | O10: 1 | Q10: 1 | S10: 1 | U10: 1 | W10: 1 | Y10: 1 | AA10: 1 | AC10: 1 | AE10: 1
B11: 이진영 | C11: 분석설계 | D11: 고급 | E11: ㈜이포넷 | F11: =SUM(I11,K11,M11,O11,Q11,S11,U11,W11,Y11,AA11,AC11,AE11) -> 11.2 | G11: =SUM(J11,L11,N11,P11,R11,T11,V11,X11,Z11,AB11,AD11,AF11) -> 2.2 | H11: =F11-G11 -> 9 | I11: 0.2 | J11: 0.2 | K11: 1 | L11: 1 | M11: 1 | N11: 1 | O11: 1 | Q11: 1 | S11: 1 | U11: 1 | W11: 1 | Y11: 1 | AA11: 1 | AC11: 1 | AE11: 1
B12: 진예은 | C12: 개발 | D12: 초급 | E12: ㈜이포넷 | F12: =SUM(I12,K12,M12,O12,Q12,S12,U12,W12,Y12,AA12,AC12,AE12) -> 11.2 | G12: =SUM(J12,L12,N12,P12,R12,T12,V12,X12,Z12,AB12,AD12,AF12) -> 2.2 | H12: =F12-G12 -> 9 | I12: 0.2 | J12: 0.2 | K12: 1 | L12: 1 | M12: 1 | N12: 1 | O12: 1 | Q12: 1 | S12: 1 | U12: 1 | W12: 1 | Y12: 1 | AA12: 1 | AC12: 1 | AE12: 1
B13: 최민정 | C13: 개발 | D13: 초급 | E13: ㈜이포넷 | F13: =SUM(I13,K13,M13,O13,Q13,S13,U13,W13,Y13,AA13,AC13,AE13) -> 11.2 | G13: =SUM(J13,L13,N13,P13,R13,T13,V13,X13,Z13,AB13,AD13,AF13) -> 2.2 | H13: =F13-G13 -> 9 | I13: 0.2 | J13: 0.2 | K13: 1 | L13: 1 | M13: 1 | N13: 1 | O13: 1 | Q13: 1 | S13: 1 | U13: 1 | W13: 1 | Y13: 1 | AA13: 1 | AC13: 1 | AE13: 1
B14: 백철민 | C14: 개발 | D14: 고급 | E14: ㈜이포넷 | F14: =SUM(I14,K14,M14,O14,Q14,S14,U14,W14,Y14,AA14,AC14,AE14) -> 5.6 | G14: =SUM(J14,L14,N14,P14,R14,T14,V14,X14,Z14,AB14,AD14,AF14) -> 1.1 | H14: =F14-G14 -> 4.5 | I14: 0.1 | J14: 0.1 | K14: 0.5 | L14: 0.5 | M14: 0.5 | N14: 0.5 | O14: 0.5 | Q14: 0.5 | S14: 0.5 | U14: 0.5 | W14: 0.5 | Y14: 0.5 | AA14: 0.5 | AC14: 0.5 | AE14: 0.5
B15: 성민주 | C15: 개발 | D15: 초급 | E15: ㈜이포넷 | F15: =SUM(I15,K15,M15,O15,Q15,S15,U15,W15,Y15,AA15,AC15,AE15) -> 5.6 | G15: =SUM(J15,L15,N15,P15,R15,T15,V15,X15,Z15,AB15,AD15,AF15) -> 1.1 | H15: =F15-G15 -> 4.5 | I15: 0.1 | J15: 0.1 | K15: 0.5 | L15: 0.5 | M15: 0.5 | N15: 0.5 | O15: 0.5 | Q15: 0.5 | S15: 0.5 | U15: 0.5 | W15: 0.5 | Y15: 0.5 | AA15: 0.5 | AC15: 0.5 | AE15: 0.5
B16: 이동하 | C16: 개발 | D16: 특급 | E16: 오엠 인터렉티브 | F16: =SUM(I16,K16,M16,O16,Q16,S16,U16,W16,Y16,AA16,AC16,AE16) -> 5 | G16: =SUM(J16,L16,N16,P16,R16,T16,V16,X16,Z16,AB16,AD16,AF16) -> 0.5 | H16: =F16-G16 -> 4.5 | M16: 0.5 | N16: 0.5 | O16: 0.5 | Q16: 0.5 | S16: 0.5 | U16: 0.5 | W16: 0.5 | Y16: 0.5 | AA16: 0.5 | AC16: 0.5 | AE16: 0.5
B17: 김다정 | C17: 개발 | D17: 고급 | E17: 오엠 인터렉티브 | F17: =SUM(I17,K17,M17,O17,Q17,S17,U17,W17,Y17,AA17,AC17,AE17) -> 10 | G17: =SUM(J17,L17,N17,P17,R17,T17,V17,X17,Z17,AB17,AD17,AF17) -> 1 | H17: =F17-G17 -> 9 | M17: 1 | N17: 1 | O17: 1 | Q17: 1 | S17: 1 | U17: 1 | W17: 1 | Y17: 1 | AA17: 1 | AC17: 1 | AE17: 1
B18: 양승현 | C18: 개발 | D18: 중급 | E18: 오엠 인터렉티브 | F18: =SUM(I18,K18,M18,O18,Q18,S18,U18,W18,Y18,AA18,AC18,AE18) -> 10 | G18: =SUM(J18,L18,N18,P18,R18,T18,V18,X18,Z18,AB18,AD18,AF18) -> 1 | H18: =F18-G18 -> 9 | M18: 1 | N18: 1 | O18: 1 | Q18: 1 | S18: 1 | U18: 1 | W18: 1 | Y18: 1 | AA18: 1 | AC18: 1 | AE18: 1
B19: 합계 | F19: =SUM(F7:F18) -> 114.6 | G19: =SUM(G7:G18) -> 20.1 | H19: =SUM(H7:H15) -> 72 | I19: =SUM(I7:I18) -> 1.6 | J19: =SUM(J7:J18) -> 1.6 | K19: =SUM(K7:K18) -> 8 | L19: =SUM(L7:L18) -> 8 | M19: =SUM(M7:M18) -> 10.5 | N19: =SUM(N7:N18) -> 10.5 | O19: =SUM(O7:O18) -> 10.5 | P19: =SUM(P7:P18) -> 0 | ... AF19: =SUM(AF7:AF18) -> 0

Sheet 진척율보고서
B2: 프로젝트 진척률 보고서
B4: 1. 프로젝트 명 | D4: ='표지'!B10 -> 판로플랫폼 고도화 및 유지관리 | I4: 누적 실적 측정 기준일 | M4: 46108
B5: 2. 프로젝트 일정 | D5: 누적 진척률 계산기간
D6: 시작일 | G6: 종료일
D7: 46048 | G7: 46387
B8: 3. 프로젝트 진척율 | D8: 구분 | G8: 가중치 | I8: 전체진척률(100%) | J8: 가중치 진척률 | N8: 비고
J9: 목표진척률 | K9: 실적진척률 | L9: 달성률 | M9: 진행상태 | N9: ○ 실적 진척률 부여 기준(각 Task) (예시)
D10: 사업관리 | G10: 10 | I10: ='1.사업관리'!$O$2 -> 0.2371134 | J10: ='1.사업관리'!$L$6 -> 0.02371134 | K10: =IF('1.사업관리'!$N$6>J10,J10,'1.사업관리'!$N$6) -> 0.02371134 | L10: =IF(IFERROR(K10/J10,0)>1,1,IFERROR(K10/J10,0)) -> 1 | M10: =IF(J10=0,"시작전", IF(L10>=0.95,"양호",IF(L10>=0.85,"지연","위험"))) -> 양호 | N10: <진척률> - 미착수 : 0% - 착수 : 20% - 수행 1단계 : 35% - 수행 2단계 : 55% - 테스트 : 70% - PL확인 : 80% - PM확인 : 95% - 완료 : 100% <상태> - 양호 : 95% 이상 - 지연 : 95% 미만 - 위험 : 90% 미만
D11: 유지보수 | E11: 챗봇 | G11: =SUM(H11:H14) -> 90 | H11: 20 | I11: ='2.챗봇'!$O$2 -> 0.15384615 | J11: ='2.챗봇'!$L$6 -> 0.030769231 | K11: =IF('2.챗봇'!$N$6>J11,J11,'2.챗봇'!$N$6) -> 0.030769231 | L11: =IF(IFERROR(K11/J11,0)>1,1,IFERROR(K11/J11,0)) -> 1 | M11: =IF(J11=0,"시작전", IF(L11>=0.95,"양호",IF(L11>=0.85,"지연","위험"))) -> 양호
E12: 티켓관리 | H12: 20 | I12: ='3.티켓관리'!$O$2 -> 0.15384615 | J12: ='3.티켓관리'!$L$6 -> 0.030769231 | K12: =IF('3.티켓관리'!$N$6>J12,J12,'3.티켓관리'!$N$6) -> 0.030769231 | L12: =IF(IFERROR(K12/J12,0)>1,1,IFERROR(K12/J12,0)) -> 1 | M12: =IF(J12=0,"시작전", IF(L12>=0.95,"양호",IF(L12>=0.85,"지연","위험"))) -> 양호
E13: 기능개선 | H13: 30 | I13: ='4.기능개선'!$O$2 -> 0.5475 | J13: ='4.기능개선'!$L$6 -> 0.1728399 | K13: =IF('4.기능개선'!$N$6>J13,J13,'4.기능개선'!$N$6) -> 0.16425 | L13: =IF(IFERROR(K13/J13,0)>1,1,IFERROR(K13/J13,0)) -> 0.9503014 | M13: =IF(J13=0,"시작전", IF(L13>=0.95,"양호",IF(L13>=0.85,"지연","위험"))) -> 양호
E14: SLA협약 | H14: 20 | I14: ='5.SLA협약'!$O$2 -> 0.37916667 | J14: ='5.SLA협약'!$L$6 -> 0.075 | K14: =IF('5.SLA협약'!$N$6>J14,J14,'5.SLA협약'!$N$6) -> 0.075 | L14: =IF(IFERROR(K14/J14,0)>1,1,IFERROR(K14/J14,0)) -> 1 | M14: =IF(J14=0,"시작전", IF(L14>=0.95,"양호",IF(L14>=0.85,"지연","위험"))) -> 양호
D15: 전체 | G15: =SUM(G10:G14) -> 100 | I15: =AVERAGE(I10:I14) -> 0.29429448 | J15: =SUM(J10:J14) -> 0.3330897 | K15: =SUM(K10:K14) -> 0.3244998 | L15: =IF(IFERROR(K15/J15,0)>1,1,IFERROR(K15/J15,0)) -> 0.97421145 | M15: =IF(L15>=0.95,"양호",IF(L15>=0.85,"지연","위험")) -> 양호

Sheet 1.사업관리
B2: 1. 사업관리 | I2: 계획진척률(누적) | K2: =(SUM(L8:L15)+SUM(L17:L19)+SUM(L21:L25)+SUM(L27:L50)+SUM(L52:L55)+SUM(L57:L61)+SUM(L63:L123))/(COUNT(L8:L15)+COUNT(L17:L19)+COUNT(L21:L25)+COUNT(L27:L50)+COUNT(L52:L55)+COUNT(L57:L61)+COUNT(L63:L123)) -> 0.2371134 | M2: 실적진척률(누적) | O2: =(SUM(N8:N15)+SUM(N17:N19)+SUM(N21:N25)+SUM(N27:N50)+SUM(N52:N55)+SUM(N57:N61)+SUM(N63:N123))/(COUNT(N8:N15)+COUNT(N17:N19)+COUNT(N21:N25)+COUNT(N27:N50)+COUNT(N52:N55)+COUNT(N57:N61)+COUNT(N63:N123)) -> 0.2371134
I3: 계획 | M3: 실적
B4: 구분 | C4: 단계 | D4: Task | F4: 산출물 | G4: 담당자 | H4: 가중치 | I4: 계획시작일 | J4: 계획종료일 | K4: 기간(day) | L4: 계획률 | M4: 상태 | N4: 진척률 | O4: 실제시작일 | P4: 실제종료일
D5: 요약 | E5: 업무내용
B6: 사업관리 | H6: ='진척율보고서'!G10 -> 10 | K6: =IF(OR(ISBLANK($I6), ISBLANK($J6)),"",NETWORKDAYS($I6,$J6)) | L6: =K2*H6/100 -> 0.02371134 | N6: =O2*H6/100 -> 0.02371134
C7: 마일스톤 | I7: =MIN(I8:I15) -> 46048 | J7: =MAX(J8:J15) -> 46372 | K7: =IF(OR(ISBLANK($I7), ISBLANK($J7)),"",NETWORKDAYS($I7,$J7)) -> 233 | L7: =SUM(L8:L15)/COUNT(L8:L15) -> 0.4 | N7: =SUM(N8:N15)/COUNT(N8:N15) -> 0.4
D8: 착수보고회
E9: 사업수행계획서 작성 및 제출 | F9: 착수계, 사업수행계획서 | G9: 장일훈 | I9: 46048 | J9: 46059 | K9: =IF(OR(ISBLANK($I9), ISBLANK($J9)),"",NETWORKDAYS($I9,$J9)) -> 10 | L9: =IF(OR(ISBLANK($I9), ISBLANK($J9)), "", IF('진척율보고서'!$M$4 < $I9, 0, IF('진척율보고서'!$M$4 >= $J9, 1, NETWORKDAYS($I9,'진척율보고서'!$M$4)/$K9))) -> 1 | M9: 완료 | N9: =IF($M9="완료",1,IF($M9="PM확인",0.95,IF($M9="PL확인",0.8,IF($M9="테스트",0.7,IF($M9="수행2단계",0.55,IF($M9="수행1단계",0.35,IF($M9="착수",0.2,IF($M9="미착수",0,"")))))))) -> 1 | O9: 46048 | P9: 46055
E10: 착수보고회 준비 및 시행 | G10: 장일훈 | I10: 46055 | J10: 46063 | K10: =IF(OR(ISBLANK($I10), ISBLANK($J10)),"",NETWORKDAYS($I10,$J10)) -> 7 | L10: =IF(OR(ISBLANK($I10), ISBLANK($J10)), "", IF('진척율보고서'!$M$4 < $I10, 0, IF('진척율보고서'!$M$4 >= $J10, 1, NETWORKDAYS($I10,'진척율보고서'!$M$4)/$K10))) -> 1 | M10: 완료 | N10: =IF($M10="완료",1,IF($M10="PM확인",0.95,IF($M10="PL확인",0.8,IF($M10="테스트",0.7,IF($M10="수행2단계",0.55,IF($M10="수행1단계",0.35,IF($M10="착수",0.2,IF($M10="미착수",0,"")))))))) -> 1 | O10: 46055 | P10: 46063
D11: 중간보고회
E12: 워크샵 및 중간보고 발표자료 작성 | F12: 중간보고 발표자료 | G12: 장일훈 | I12: 46211 | J12: 46211 | K12: =IF(OR(ISBLANK($I12), ISBLANK($J12)),"",NETWORKDAYS($I12,$J12)) -> 1 | L12: =IF(OR(ISBLANK($I12), ISBLANK($J12)), "", IF('진척율보고서'!$M$4 < $I12, 0, IF('진척율보고서'!$M$4 >= $J12, 1, NETWORKDAYS($I12,'진척율보고서'!$M$4)/$K12))) -> 0 | M12: 미착수 | N12: =IF($M12="완료",1,IF($M12="PM확인",0.95,IF($M12="PL확인",0.8,IF($M12="테스트",0.7,IF($M12="수행2단계",0.55,IF($M12="수행1단계",0.35,IF($M12="착수",0.2,IF($M12="미착수",0,"")))))))) -> 0
D13: 완료보고회
E14: 완료보고 발표자료 작성 및 제출 | F14: 완료보고서 | G14: 장일훈 | I14: 46363 | J14: 46367 | K14: =IF(OR(ISBLANK($I14), ISBLANK($J14)),"",NETWORKDAYS($I14,$J14)) -> 5 | L14: =IF(OR(ISBLANK($I14), ISBLANK($J14)), "", IF('진척율보고서'!$M$4 < $I14, 0, IF('진척율보고서'!$M$4 >= $J14, 1, NETWORKDAYS($I14,'진척율보고서'!$M$4)/$K14))) -> 0 | M14: 미착수 | N14: =IF($M14="완료",1,IF($M14="PM확인",0.95,IF($M14="PL확인",0.8,IF($M14="테스트",0.7,IF($M14="수행2단계",0.55,IF($M14="수행1단계",0.35,IF($M14="착수",0.2,IF($M14="미착수",0,"")))))))) -> 0
E15: 완료보고회 준비 및 시행 | G15: 사업단 | I15: 46372 | J15: 46372 | K15: =IF(OR(ISBLANK($I15), ISBLANK($J15)),"",NETWORKDAYS($I15,$J15)) -> 1 | L15: =IF(OR(ISBLANK($I15), ISBLANK($J15)), "", IF('진척율보고서'!$M$4 < $I15, 0, IF('진척율보고서'!$M$4 >= $J15, 1, NETWORKDAYS($I15,'진척율보고서'!$M$4)/$K15))) -> 0 | M15: 미착수 | N15: =IF($M15="완료",1,IF($M15="PM확인",0.95,IF($M15="PL확인",0.8,IF($M15="테스트",0.7,IF($M15="수행2단계",0.55,IF($M15="수행1단계",0.35,IF($M15="착수",0.2,IF($M15="미착수",0,"")))))))) -> 0
C16: 착수 및 환경구성 | I16: =MIN(I17:I19) -> 46048 | J16: =MAX(J17:J19) -> 46052 | K16: =IF(OR(ISBLANK($I16), ISBLANK($J16)),"",NETWORKDAYS($I16,$J16)) -> 5 | L16: =SUM(L17:L19)/COUNT(L17:L19) -> 1 | N16: =SUM(N17:N19)/COUNT(N17:N19) -> 1
D17: 업무 환경 구성
E18: 사무실 및 네트워크 환경 구성 | G18: 사업단 | I18: 46048 | J18: 46052 | K18: =IF(OR(ISBLANK($I18), ISBLANK($J18)),"",NETWORKDAYS($I18,$J18)) -> 5 | L18: =IF(OR(ISBLANK($I18), ISBLANK($J18)), "", IF('진척율보고서'!$M$4 < $I18, 0, IF('진척율보고서'!$M$4 >= $J18, 1, NETWORKDAYS($I18,'진척율보고서'!$M$4)/$K18))) -> 1 | M18: 완료 | N18: =IF($M18="완료",1,IF($M18="PM확인",0.95,IF($M18="PL확인",0.8,IF($M18="테스트",0.7,IF($M18="수행2단계",0.55,IF($M18="수행1단계",0.35,IF($M18="착수",0.2,IF($M18="미착수",0,"")))))))) -> 1 | O18: 46048 | P18: 46048
E19: 투입인력 장비 구성 | G19: 사업단 | I19: 46048 | J19: 46052 | K19: =IF(OR(ISBLANK($I19), ISBLANK($J19)),"",NETWORKDAYS($I19,$J19)) -> 5 | L19: =IF(OR(ISBLANK($I19), ISBLANK($J19)), "", IF('진척율보고서'!$M$4 < $I19, 0, IF('진척율보고서'!$M$4 >= $J19, 1, NETWORKDAYS($I19,'진척율보고서'!$M$4)/$K19))) -> 1 | M19: 완료 | N19: =IF($M19="완료",1,IF($M19="PM확인",0.95,IF($M19="PL확인",0.8,IF($M19="테스트",0.7,IF($M19="수행2단계",0.55,IF($M19="수행1단계",0.35,IF($M19="착수",0.2,IF($M19="미착수",0,"")))))))) -> 1 | O19: 46048 | P19: 46048
C20: 사업분석 및 요구사항 정의 | I20: =MIN(I21:I25) -> 46048 | J20: =MAX(J21:J25) -> 46080 | K20: =IF(OR(ISBLANK($I20), ISBLANK($J20)),"",NETWORKDAYS($I20,$J20)) -> 25 | L20: =SUM(L21:L25)/COUNT(L21:L25) -> 1 | N20: =SUM(N21:N25)/COUNT(N21:N25) -> 1
D21: WBS 및 요구사항 정의 (기능개선)
E22: WBS 작성 | F22: WBS | G22: 장일훈 | I22: 46048 | J22: 46059 | K22: =IF(OR(ISBLANK($I22), ISBLANK($J22)),"",NETWORKDAYS($I22,$J22)) -> 10 | L22: =IF(OR(ISBLANK($I22), ISBLANK($J22)), "", IF('진척율보고서'!$M$4 < $I22, 0, IF('진척율보고서'!$M$4 >= $J22, 1, NETWORKDAYS($I22,'진척율보고서'!$M$4)/$K22))) -> 1 | M22: 완료 | N22: =IF($M22="완료",1,IF($M22="PM확인",0.95,IF($M22="PL확인",0.8,IF($M22="테스트",0.7,IF($M22="수행2단계",0.55,IF($M22="수행1단계",0.35,IF($M22="착수",0.2,IF($M22="미착수",0,"")))))))) -> 1 | O22: 46048 | P22: 46059
E23: 요구사항 분석 및 정의 1차 | F23: 요구사항정의서 | G23: 업무PL | I23: 46055 | J23: 46059 | K23: =IF(OR(ISBLANK($I23), ISBLANK($J23)),"",NETWORKDAYS($I23,$J23)) -> 5 | L23: =IF(OR(ISBLANK($I23), ISBLANK($J23)), "", IF('진척율보고서'!$M$4 < $I23, 0, IF('진척율보고서'!$M$4 >= $J23, 1, NETWORKDAYS($I23,'진척율보고서'!$M$4)/$K23))) -> 1 | M23: 완료 | N23: =IF($M23="완료",1,IF($M23="PM확인",0.95,IF($M23="PL확인",0.8,IF($M23="테스트",0.7,IF($M23="수행2단계",0.55,IF($M23="수행1단계",0.35,IF($M23="착수",0.2,IF($M23="미착수",0,"")))))))) -> 1 | O23: 46055 | P23: 46059
E24: 요구사항 분석 및 정의 2차 | F24: 요구사항추적표 | G24: 업무PL | I24: 46062 | J24: 46066 | K24: =IF(OR(ISBLANK($I24), ISBLANK($J24)),"",NETWORKDAYS($I24,$J24)) -> 5 | L24: =IF(OR(ISBLANK($I24), ISBLANK($J24)), "", IF('진척율보고서'!$M$4 < $I24, 0, IF('진척율보고서'!$M$4 >= $J24, 1, NETWORKDAYS($I24,'진척율보고서'!$M$4)/$K24))) -> 1 | M24: 완료 | N24: =IF($M24="완료",1,IF($M24="PM확인",0.95,IF($M24="PL확인",0.8,IF($M24="테스트",0.7,IF($M24="수행2단계",0.55,IF($M24="수행1단계",0.35,IF($M24="착수",0.2,IF($M24="미착수",0,"")))))))) -> 1 | O24: 46062 | P24: 46066
E25: 요구사항 분석 및 정의 3차 | F25: 요구사항추적표 | G25: 업무PL | I25: 46076 | J25: 46080 | K25: =IF(OR(ISBLANK($I25), ISBLANK($J25)),"",NETWORKDAYS($I25,$J25)) -> 5 | L25: =IF(OR(ISBLANK($I25), ISBLANK($J25)), "", IF('진척율보고서'!$M$4 < $I25, 0, IF('진척율보고서'!$M$4 >= $J25, 1, NETWORKDAYS($I25,'진척율보고서'!$M$4)/$K25))) -> 1 | M25: 완료 | N25: =IF($M25="완료",1,IF($M25="PM확인",0.95,IF($M25="PL확인",0.8,IF($M25="테스트",0.7,IF($M25="수행2단계",0.55,IF($M25="수행1단계",0.35,IF($M25="착수",0.2,IF($M25="미착수",0,"")))))))) -> 1 | O25: 46076 | P25: 46080
C26: 보안관리 | I26: =MIN(I27:I50) -> 46048 | J26: =MAX(J27:J50) -> 46387 | K26: =IF(OR(ISBLANK($I26), ISBLANK($J26)),"",NETWORKDAYS($I26,$J26)) -> 244 | L26: =SUM(L27:L50)/COUNT(L27:L50) -> 0.33333333 | N26: =SUM(N27:N50)/COUNT(N27:N50) -> 0.33333333
D27: 물리적 보안 시행
E28: 사무실 출입 보안 장치 구성 | G28: 사업단 | I28: 46048 | J28: 46052 | K28: =IF(OR(ISBLANK($I28), ISBLANK($J28)),"",NETWORKDAYS($I28,$J28)) -> 5 | L28: =IF(OR(ISBLANK($I28), ISBLANK($J28)), "", IF('진척율보고서'!$M$4 < $I28, 0, IF('진척율보고서'!$M$4 >= $J28, 1, NETWORKDAYS($I28,'진척율보고서'!$M$4)/$K28))) -> 1 | M28: 완료 | N28: =IF($M28="완료",1,IF($M28="PM확인",0.95,IF($M28="PL확인",0.8,IF($M28="테스트",0.7,IF($M28="수행2단계",0.55,IF($M28="수행1단계",0.35,IF($M28="착수",0.2,IF($M28="미착수",0,"")))))))) -> 1 | O28: 46048 | P28: 46048
E29: 사무실 CCTV 신규 설치 | G29: 사업단 | I29: 46048 | J29: 46052 | K29: =IF(OR(ISBLANK($I29), ISBLANK($J29)),"",NETWORKDAYS($I29,$J29)) -> 5 | L29: =IF(OR(ISBLANK($I29), ISBLANK($J29)), "", IF('진척율보고서'!$M$4 < $I29, 0, IF('진척율보고서'!$M$4 >= $J29, 1, NETWORKDAYS($I29,'진척율보고서'!$M$4)/$K29))) -> 1 | M29: 완료 | N29: =IF($M29="완료",1,IF($M29="PM확인",0.95,IF($M29="PL확인",0.8,IF($M29="테스트",0.7,IF($M29="수행2단계",0.55,IF($M29="수행1단계",0.35,IF($M29="착수",0.2,IF($M29="미착수",0,"")))))))) -> 1 | O29: 46048 | P29: 46048
E30: 투입인력 PC 보안솔루션 설치 | G30: 사업단 | I30: 46048 | J30: 46052 | K30: =IF(OR(ISBLANK($I30), ISBLANK($J30)),"",NETWORKDAYS($I30,$J30)) -> 5 | L30: =IF(OR(ISBLANK($I30), ISBLANK($J30)), "", IF('진척율보고서'!$M$4 < $I30, 0, IF('진척율보고서'!$M$4 >= $J30, 1, NETWORKDAYS($I30,'진척율보고서'!$M$4)/$K30))) -> 1 | M30: 완료 | N30: =IF($M30="완료",1,IF($M30="PM확인",0.95,IF($M30="PL확인",0.8,IF($M30="테스트",0.7,IF($M30="수행2단계",0.55,IF($M30="수행1단계",0.35,IF($M30="착수",0.2,IF($M30="미착수",0,"")))))))) -> 1 | O30: 46048 | P30: 46048
D31: 보안산출물 작성
E32: 투입인력 보안서약서 작성 및 제출 | F32: 보안서약서 | G32: 사업단 | I32: 46055 | J32: 46066 | K32: =IF(OR(ISBLANK($I32), ISBLANK($J32)),"",NETWORKDAYS($I32,$J32)) -> 10 | L32: =IF(OR(ISBLANK($I32), ISBLANK($J32)), "", IF('진척율보고서'!$M$4 < $I32, 0, IF('진척율보고서'!$M$4 >= $J32, 1, NETWORKDAYS($I32,'진척율보고서'!$M$4)/$K32))) -> 1 | M32: 완료 | N32: =IF($M32="완료",1,IF($M32="PM확인",0.95,IF($M32="PL확인",0.8,IF($M32="테스트",0.7,IF($M32="수행2단계",0.55,IF($M32="수행1단계",0.35,IF($M32="착수",0.2,IF($M32="미착수",0,"")))))))) -> 1 | O32: 46055 | P32: 46066
E33: 개인정보 보안교육 | F33: 개인정보보안교육 결과 | G33: 사업단 | I33: 46055 | J33: 46055 | K33: =IF(OR(ISBLANK($I33), ISBLANK($J33)),"",NETWORKDAYS($I33,$J33)) -> 1 | L33: =IF(OR(ISBLANK($I33), ISBLANK($J33)), "", IF('진척율보고서'!$M$4 < $I33, 0, IF('진척율보고서'!$M$4 >= $J33, 1, NETWORKDAYS($I33,'진척율보고서'!$M$4)/$K33))) -> 1 | M33: 완료 | N33: =IF($M33="완료",1,IF($M33="PM확인",0.95,IF($M33="PL확인",0.8,IF($M33="테스트",0.7,IF($M33="수행2단계",0.55,IF($M33="수행1단계",0.35,IF($M33="착수",0.2,IF($M33="미착수",0,"")))))))) -> 1 | O33: 46055 | P33: 46055
E34: 사무실 출입관리대장 작성 | F34: 출입관리대장 | G34: 사업단 | I34: 46357 | J34: 46387 | K34: =IF(OR(ISBLANK($I34), ISBLANK($J34)),"",NETWORKDAYS($I34,$J34)) -> 23 | L34: =IF(OR(ISBLANK($I34), ISBLANK($J34)), "", IF('진척율보고서'!$M$4 < $I34, 0, IF('진척율보고서'!$M$4 >= $J34, 1, NETWORKDAYS($I34,'진척율보고서'!$M$4)/$K34))) -> 0 | M34: 미착수 | N34: =IF($M34="완료",1,IF($M34="PM확인",0.95,IF($M34="PL확인",0.8,IF($M34="테스트",0.7,IF($M34="수행2단계",0.55,IF($M34="수행1단계",0.35,IF($M34="착수",0.2,IF($M34="미착수",0,"")))))))) -> 0
E35: 전산장비 관리대장 작성 | F35: 전산장비 관리대장 | G35: 사업단 | I35: 46357 | J35: 46387 | K35: =IF(OR(ISBLANK($I35), ISBLANK($J35)),"",NETWORKDAYS($I35,$J35)) -> 23 | L35: =IF(OR(ISBLANK($I35), ISBLANK($J35)), "", IF('진척율보고서'!$M$4 < $I35, 0, IF('진척율보고서'!$M$4 >= $J35, 1, NETWORKDAYS($I35,'진척율보고서'!$M$4)/$K35))) -> 0 | M35: 미착수 | N35: =IF($M35="완료",1,IF($M35="PM확인",0.95,IF($M35="PL확인",0.8,IF($M35="테스트",0.7,IF($M35="수행2단계",0.55,IF($M35="수행1단계",0.35,IF($M35="착수",0.2,IF($M35="미착수",0,"")))))))) -> 0
E36: 자료제공 관리대장 작성 | F36: 자료제공 관리대장 | G36: 사업단 | I36: 46357 | J36: 46387 | K36: =IF(OR(ISBLANK($I36), ISBLANK($J36)),"",NETWORKDAYS($I36,$J36)) -> 23 | L36: =IF(OR(ISBLANK($I36), ISBLANK($J36)), "", IF('진척율보고서'!$M$4 < $I36, 0, IF('진척율보고서'!$M$4 >= $J36, 1, NETWORKDAYS($I36,'진척율보고서'!$M$4)/$K36))) -> 0 | M36: 미착수 | N36: =IF($M36="완료",1,IF($M36="PM확인",0.95,IF($M36="PL확인",0.8,IF($M36="테스트",0.7,IF($M36="수행2단계",0.55,IF($M36="수행1단계",0.35,IF($M36="착수",0.2,IF($M36="미착수",0,"")))))))) -> 0
E37: 반출입 관리대장 작성 | F37: 반출입 관리대장 | G37: 사업단 | I37: 46357 | J37: 46387 | K37: =IF(OR(ISBLANK($I37), ISBLANK($J37)),"",NETWORKDAYS($I37,$J37)) -> 23 | L37: =IF(OR(ISBLANK($I37), ISBLANK($J37)), "", IF('진척율보고서'!$M$4 < $I37, 0, IF('진척율보고서'!$M$4 >= $J37, 1, NETWORKDAYS($I37,'진척율보고서'!$M$4)/$K37))) -> 0 | M37: 미착수 | N37: =IF($M37="완료",1,IF($M37="PM확인",0.95,IF($M37="PL확인",0.8,IF($M37="테스트",0.7,IF($M37="수행2단계",0.55,IF($M37="수행1단계",0.35,IF($M37="착수",0.2,IF($M37="미착수",0,"")))))))) -> 0
E38: 프로젝트 투입인력 검토 및 확정 | F38: 투입인력현황 | G38: 사업단 | I38: 46048 | J38: 46059 | K38: =IF(OR(ISBLANK($I38), ISBLANK($J38)),"",NETWORKDAYS($I38,$J38)) -> 10 | L38: =IF(OR(ISBLANK($I38), ISBLANK($J38)), "", IF('진척율보고서'!$M$4 < $I38, 0, IF('진척율보고서'!$M$4 >= $J38, 1, NETWORKDAYS($I38,'진척율보고서'!$M$4)/$K38))) -> 1 | M38: 완료 | N38: =IF($M38="완료",1,IF($M38="PM확인",0.95,IF($M38="PL확인",0.8,IF($M38="테스트",0.7,IF($M38="수행2단계",0.55,IF($M38="수행1단계",0.35,IF($M38="착수",0.2,IF($M38="미착수",0,"")))))))) -> 1 | O38: 46055 | P38: 46059
D39: 보안교육(신규 투입 인원 발생 시)
E40: 02월 보안교육 | F40: 보안교육결과서 | G40: 사업단 | I40: 46076 | J40: 46076 | K40: =IF(OR(ISBLANK($I40), ISBLANK($J40)),"",NETWORKDAYS($I40,$J40)) -> 1 | L40: =IF(OR(ISBLANK($I40), ISBLANK($J40)), "", IF('진척율보고서'!$M$4 < $I40, 0, IF('진척율보고서'!$M$4 >= $J40, 1, NETWORKDAYS($I40,'진척율보고서'!$M$4)/$K40))) -> 1 | M40: 완료 | N40: =IF($M40="완료",1,IF($M40="PM확인",0.95,IF($M40="PL확인",0.8,IF($M40="테스트",0.7,IF($M40="수행2단계",0.55,IF($M40="수행1단계",0.35,IF($M40="착수",0.2,IF($M40="미착수",0,"")))))))) -> 1 | O40: 46076 | P40: 46076
E41: 03월 보안교육 | F41: 보안교육결과서 | G41: 사업단 | I41: 46111 | J41: 46111 | K41: =IF(OR(ISBLANK($I41), ISBLANK($J41)),"",NETWORKDAYS($I41,$J41)) -> 1 | L41: =IF(OR(ISBLANK($I41), ISBLANK($J41)), "", IF('진척율보고서'!$M$4 < $I41, 0, IF('진척율보고서'!$M$4 >= $J41, 1, NETWORKDAYS($I41,'진척율보고서'!$M$4)/$K41))) -> 0 | M41: 미착수 | N41: =IF($M41="완료",1,IF($M41="PM확인",0.95,IF($M41="PL확인",0.8,IF($M41="테스트",0.7,IF($M41="수행2단계",0.55,IF($M41="수행1단계",0.35,IF($M41="착수",0.2,IF($M41="미착수",0,"")))))))) -> 0
...

Sheet 2.챗봇
B2: 2. 챗봇 | I2: 계획진척률(누적) | K2: =(SUM(L8:L15)+SUM(L17:L23)+SUM(L25:L27))/(COUNT(L8:L15)+COUNT(L17:L23)+COUNT(L25:L27)) -> 0.15384615 | M2: 실적진척률(누적) | O2: =(SUM(N8:N15)+SUM(N17:N23)+SUM(N25:N27))/(COUNT(N8:N15)+COUNT(N17:N23)+COUNT(N25:N27)) -> 0.15384615
I3: 계획 | M3: 실적
B4: 구분 | C4: 단계 | D4: 업무 | F4: 산출물 | G4: 담당자 | H4: 가중치 | I4: 계획시작일 | J4: 계획종료일 | K4: 기간(day) | L4: 진척률 | M4: 상태 | N4: 실적진척률 | O4: 실제시작일 | P4: 실제종료일
D5: 요약 | E5: 업무내용
B6: 티켓관리시스템 도입 및 구축 | H6: ='진척율보고서'!H11 -> 20 | K6: =IF(OR(ISBLANK($I6), ISBLANK($J6)),"",NETWORKDAYS($I6,$J6)) | L6: =K2*H6/100 -> 0.030769231 | N6: =O2*H6/100 -> 0.030769231
C7: 분석/설계 | I7: =MIN(I8:I15) -> 46076 | J7: =MAX(J8:J15) -> 46200 | K7: =IF(OR(ISBLANK($I7), ISBLANK($J7)),"",NETWORKDAYS($I7,$J7)) -> 90 | L7: =SUM(L8:L15)/COUNT(L8:L15) -> 0.33333333 | N7: =SUM(N8:N15)/COUNT(N8:N15) -> 0.33333333
D8: 솔루션 분석 및 요구사항 정의
E9: RFP 검토 | G9: 사업단 | I9: 46076 | J9: 46080 | K9: =IF(OR(ISBLANK($I9), ISBLANK($J9)),"",NETWORKDAYS($I9,$J9)) -> 5 | L9: =IF(OR(ISBLANK($I9), ISBLANK($J9)), "", IF('진척율보고서'!$M$4 < $I9, 0, IF('진척율보고서'!$M$4 >= $J9, 1, NETWORKDAYS($I9,'진척율보고서'!$M$4)/$K9))) -> 1 | M9: 완료 | N9: =IF($M9="완료",1,IF($M9="PM확인",0.95,IF($M9="PL확인",0.8,IF($M9="테스트",0.7,IF($M9="수행2단계",0.55,IF($M9="수행1단계",0.35,IF($M9="착수",0.2,IF($M9="미착수",0,"")))))))) -> 1
E10: 솔루션 기능 시연 | G10: 진흥원, 사업단 | I10: 46084 | J10: 46094 | K10: =IF(OR(ISBLANK($I10), ISBLANK($J10)),"",NETWORKDAYS($I10,$J10)) -> 9 | L10: =IF(OR(ISBLANK($I10), ISBLANK($J10)), "", IF('진척율보고서'!$M$4 < $I10, 0, IF('진척율보고서'!$M$4 >= $J10, 1, NETWORKDAYS($I10,'진척율보고서'!$M$4)/$K10))) -> 1 | M10: 완료 | N10: =IF($M10="완료",1,IF($M10="PM확인",0.95,IF($M10="PL확인",0.8,IF($M10="테스트",0.7,IF($M10="수행2단계",0.55,IF($M10="수행1단계",0.35,IF($M10="착수",0.2,IF($M10="미착수",0,"")))))))) -> 1
E11: 솔루션 도입 최종 검토(최종 검토 후 아래 일정 수행) | G11: 진흥원, 사업단 | I11: 46167 | J11: 46173 | K11: =IF(OR(ISBLANK($I11), ISBLANK($J11)),"",NETWORKDAYS($I11,$J11)) -> 5 | L11: =IF(OR(ISBLANK($I11), ISBLANK($J11)), "", IF('진척율보고서'!$M$4 < $I11, 0, IF('진척율보고서'!$M$4 >= $J11, 1, NETWORKDAYS($I11,'진척율보고서'!$M$4)/$K11))) -> 0 | M11: 미착수 | N11: =IF($M11="완료",1,IF($M11="PM확인",0.95,IF($M11="PL확인",0.8,IF($M11="테스트",0.7,IF($M11="수행2단계",0.55,IF($M11="수행1단계",0.35,IF($M11="착수",0.2,IF($M11="미착수",0,"")))))))) -> 0
E12: 요구사항 취합 및 정의 | G12: 사업단 | I12: 46196 | J12: 46200 | K12: =IF(OR(ISBLANK($I12), ISBLANK($J12)),"",NETWORKDAYS($I12,$J12)) -> 4 | L12: =IF(OR(ISBLANK($I12), ISBLANK($J12)), "", IF('진척율보고서'!$M$4 < $I12, 0, IF('진척율보고서'!$M$4 >= $J12, 1, NETWORKDAYS($I12,'진척율보고서'!$M$4)/$K12))) -> 0 | M12: 미착수 | N12: =IF($M12="완료",1,IF($M12="PM확인",0.95,IF($M12="PL확인",0.8,IF($M12="테스트",0.7,IF($M12="수행2단계",0.55,IF($M12="수행1단계",0.35,IF($M12="착수",0.2,IF($M12="미착수",0,"")))))))) -> 0
D13: 커스터마이징 설계
E14: 커스터마이징 범위 정의 | G14: 사업단 | I14: 46174 | J14: 46185 | K14: =IF(OR(ISBLANK($I14), ISBLANK($J14)),"",NETWORKDAYS($I14,$J14)) -> 10 | L14: =IF(OR(ISBLANK($I14), ISBLANK($J14)), "", IF('진척율보고서'!$M$4 < $I14, 0, IF('진척율보고서'!$M$4 >= $J14, 1, NETWORKDAYS($I14,'진척율보고서'!$M$4)/$K14))) -> 0 | M14: 미착수 | N14: =IF($M14="완료",1,IF($M14="PM확인",0.95,IF($M14="PL확인",0.8,IF($M14="테스트",0.7,IF($M14="수행2단계",0.55,IF($M14="수행1단계",0.35,IF($M14="착수",0.2,IF($M14="미착수",0,"")))))))) -> 0
E15: 요구사항 기능 매핑 | G15: 사업단 | I15: 46188 | J15: 46192 | K15: =IF(OR(ISBLANK($I15), ISBLANK($J15)),"",NETWORKDAYS($I15,$J15)) -> 5 | L15: =IF(OR(ISBLANK($I15), ISBLANK($J15)), "", IF('진척율보고서'!$M$4 < $I15, 0, IF('진척율보고서'!$M$4 >= $J15, 1, NETWORKDAYS($I15,'진척율보고서'!$M$4)/$K15))) -> 0 | M15: 미착수 | N15: =IF($M15="완료",1,IF($M15="PM확인",0.95,IF($M15="PL확인",0.8,IF($M15="테스트",0.7,IF($M15="수행2단계",0.55,IF($M15="수행1단계",0.35,IF($M15="착수",0.2,IF($M15="미착수",0,"")))))))) -> 0
C16: 설치 및 커스터마이징 | I16: =MIN(I17:I23) -> 46195 | J16: =MAX(J17:J23) -> 46295 | K16: =IF(OR(ISBLANK($I16), ISBLANK($J16)),"",NETWORKDAYS($I16,$J16)) -> 73 | L16: =SUM(L17:L23)/COUNT(L17:L23) -> 0 | N16: =SUM(N17:N23)/COUNT(N17:N23) -> 0
D17: 솔루션 설치
E18: 솔루션 설치 및 설정 | G18: 사업단 | I18: 46195 | J18: 46199 | K18: =IF(OR(ISBLANK($I18), ISBLANK($J18)),"",NETWORKDAYS($I18,$J18)) -> 5 | L18: =IF(OR(ISBLANK($I18), ISBLANK($J18)), "", IF('진척율보고서'!$M$4 < $I18, 0, IF('진척율보고서'!$M$4 >= $J18, 1, NETWORKDAYS($I18,'진척율보고서'!$M$4)/$K18))) -> 0 | M18: 미착수 | N18: =IF($M18="완료",1,IF($M18="PM확인",0.95,IF($M18="PL확인",0.8,IF($M18="테스트",0.7,IF($M18="수행2단계",0.55,IF($M18="수행1단계",0.35,IF($M18="착수",0.2,IF($M18="미착수",0,"")))))))) -> 0
E19: 솔루션 기본 기능 테스트 | G19: 사업단 | I19: 46202 | J19: 46206 | K19: =IF(OR(ISBLANK($I19), ISBLANK($J19)),"",NETWORKDAYS($I19,$J19)) -> 5 | L19: =IF(OR(ISBLANK($I19), ISBLANK($J19)), "", IF('진척율보고서'!$M$4 < $I19, 0, IF('진척율보고서'!$M$4 >= $J19, 1, NETWORKDAYS($I19,'진척율보고서'!$M$4)/$K19))) -> 0 | M19: 미착수 | N19: =IF($M19="완료",1,IF($M19="PM확인",0.95,IF($M19="PL확인",0.8,IF($M19="테스트",0.7,IF($M19="수행2단계",0.55,IF($M19="수행1단계",0.35,IF($M19="착수",0.2,IF($M19="미착수",0,"")))))))) -> 0
D20: 커스터마이징 구현
E21: 커스터마이징 대상 화면 설계 | G21: 사업단 | I21: 46209 | J21: 46234 | K21: =IF(OR(ISBLANK($I21), ISBLANK($J21)),"",NETWORKDAYS($I21,$J21)) -> 20 | L21: =IF(OR(ISBLANK($I21), ISBLANK($J21)), "", IF('진척율보고서'!$M$4 < $I21, 0, IF('진척율보고서'!$M$4 >= $J21, 1, NETWORKDAYS($I21,'진척율보고서'!$M$4)/$K21))) -> 0 | M21: 미착수 | N21: =IF($M21="완료",1,IF($M21="PM확인",0.95,IF($M21="PL확인",0.8,IF($M21="테스트",0.7,IF($M21="수행2단계",0.55,IF($M21="수행1단계",0.35,IF($M21="착수",0.2,IF($M21="미착수",0,"")))))))) -> 0
E22: 커스터마이징 대상 개발(향 후 일정 상세회 예정) | G22: 사업단 | I22: 46237 | J22: 46283 | K22: =IF(OR(ISBLANK($I22), ISBLANK($J22)),"",NETWORKDAYS($I22,$J22)) -> 35 | L22: =IF(OR(ISBLANK($I22), ISBLANK($J22)), "", IF('진척율보고서'!$M$4 < $I22, 0, IF('진척율보고서'!$M$4 >= $J22, 1, NETWORKDAYS($I22,'진척율보고서'!$M$4)/$K22))) -> 0 | M22: 미착수 | N22: =IF($M22="완료",1,IF($M22="PM확인",0.95,IF($M22="PL확인",0.8,IF($M22="테스트",0.7,IF($M22="수행2단계",0.55,IF($M22="수행1단계",0.35,IF($M22="착수",0.2,IF($M22="미착수",0,"")))))))) -> 0
E23: 솔루션 테스트 | G23: 사업단 | I23: 46286 | J23: 46295 | K23: =IF(OR(ISBLANK($I23), ISBLANK($J23)),"",NETWORKDAYS($I23,$J23)) -> 8 | L23: =IF(OR(ISBLANK($I23), ISBLANK($J23)), "", IF('진척율보고서'!$M$4 < $I23, 0, IF('진척율보고서'!$M$4 >= $J23, 1, NETWORKDAYS($I23,'진척율보고서'!$M$4)/$K23))) -> 0 | M23: 미착수 | N23: =IF($M23="완료",1,IF($M23="PM확인",0.95,IF($M23="PL확인",0.8,IF($M23="테스트",0.7,IF($M23="수행2단계",0.55,IF($M23="수행1단계",0.35,IF($M23="착수",0.2,IF($M23="미착수",0,"")))))))) -> 0
C24: 이행 | I24: =MIN(I25:I27) -> 46296 | J24: =MAX(J25:J27) -> 46311 | K24: =IF(OR(ISBLANK($I24), ISBLANK($J24)),"",NETWORKDAYS($I24,$J24)) -> 12 | L24: =SUM(L25:L27)/COUNT(L25:L27) -> 0 | N24: =SUM(N25:N27)/COUNT(N25:N27) -> 0
D25: 이행
A26: ` | E26: 통계솔루션 운영 매뉴얼 작성 | G26: 사업단 | I26: 46296 | J26: 46311 | K26: =IF(OR(ISBLANK($I26), ISBLANK($J26)),"",NETWORKDAYS($I26,$J26)) -> 12 | L26: =IF(OR(ISBLANK($I26), ISBLANK($J26)), "", IF('진척율보고서'!$M$4 < $I26, 0, IF('진척율보고서'!$M$4 >= $J26, 1, NETWORKDAYS($I26,'진척율보고서'!$M$4)/$K26))) -> 0 | M26: 미착수 | N26: =IF($M26="완료",1,IF($M26="PM확인",0.95,IF($M26="PL확인",0.8,IF($M26="테스트",0.7,IF($M26="수행2단계",0.55,IF($M26="수행1단계",0.35,IF($M26="착수",0.2,IF($M26="미착수",0,"")))))))) -> 0
E27: 솔루션 최종 오픈 | G27: 사업단 | I27: 46296 | J27: 46296 | K27: =IF(OR(ISBLANK($I27), ISBLANK($J27)),"",NETWORKDAYS($I27,$J27)) -> 1 | L27: =IF(OR(ISBLANK($I27), ISBLANK($J27)), "", IF('진척율보고서'!$M$4 < $I27, 0, IF('진척율보고서'!$M$4 >= $J27, 1, NETWORKDAYS($I27,'진척율보고서'!$M$4)/$K27))) -> 0 | M27: 미착수 | N27: =IF($M27="완료",1,IF($M27="PM확인",0.95,IF($M27="PL확인",0.8,IF($M27="테스트",0.7,IF($M27="수행2단계",0.55,IF($M27="수행1단계",0.35,IF($M27="착수",0.2,IF($M27="미착수",0,"")))))))) -> 0

Sheet 3.티켓관리
B2: 3. 티켓관리 | I2: 계획진척률(누적) | K2: =(SUM(L8:L15)+SUM(L17:L23)+SUM(L25:L27))/(COUNT(L8:L15)+COUNT(L17:L23)+COUNT(L25:L27)) -> 0.15384615 | M2: 실적진척률(누적) | O2: =(SUM(N8:N15)+SUM(N17:N23)+SUM(N25:N27))/(COUNT(N8:N15)+COUNT(N17:N23)+COUNT(N25:N27)) -> 0.15384615
I3: 계획 | M3: 실적
B4: 구분 | C4: 단계 | D4: 업무 | F4: 산출물 | G4: 담당자 | H4: 가중치 | I4: 계획시작일 | J4: 계획종료일 | K4: 기간(day) | L4: 진척률 | M4: 상태 | N4: 실적진척률 | O4: 실제시작일 | P4: 실제종료일
D5: 요약 | E5: 업무내용
B6: 티켓관리시스템 도입 및 구축 | H6: ='진척율보고서'!H11 -> 20 | K6: =IF(OR(ISBLANK($I6), ISBLANK($J6)),"",NETWORKDAYS($I6,$J6)) | L6: =K2*H6/100 -> 0.030769231 | N6: =O2*H6/100 -> 0.030769231
C7: 분석/설계 | I7: =MIN(I8:I15) -> 46076 | J7: =MAX(J8:J15) -> 46200 | K7: =IF(OR(ISBLANK($I7), ISBLANK($J7)),"",NETWORKDAYS($I7,$J7)) -> 90 | L7: =SUM(L8:L15)/COUNT(L8:L15) -> 0.33333333 | N7: =SUM(N8:N15)/COUNT(N8:N15) -> 0.33333333
D8: 솔루션 분석 및 요구사항 정의
E9: RFP 검토 | G9: 사업단 | I9: 46076 | J9: 46080 | K9: =IF(OR(ISBLANK($I9), ISBLANK($J9)),"",NETWORKDAYS($I9,$J9)) -> 5 | L9: =IF(OR(ISBLANK($I9), ISBLANK($J9)), "", IF('진척율보고서'!$M$4 < $I9, 0, IF('진척율보고서'!$M$4 >= $J9, 1, NETWORKDAYS($I9,'진척율보고서'!$M$4)/$K9))) -> 1 | M9: 완료 | N9: =IF($M9="완료",1,IF($M9="PM확인",0.95,IF($M9="PL확인",0.8,IF($M9="테스트",0.7,IF($M9="수행2단계",0.55,IF($M9="수행1단계",0.35,IF($M9="착수",0.2,IF($M9="미착수",0,"")))))))) -> 1
E10: 솔루션 기능 시연 | G10: 진흥원, 사업단 | I10: 46084 | J10: 46094 | K10: =IF(OR(ISBLANK($I10), ISBLANK($J10)),"",NETWORKDAYS($I10,$J10)) -> 9 | L10: =IF(OR(ISBLANK($I10), ISBLANK($J10)), "", IF('진척율보고서'!$M$4 < $I10, 0, IF('진척율보고서'!$M$4 >= $J10, 1, NETWORKDAYS($I10,'진척율보고서'!$M$4)/$K10))) -> 1 | M10: 완료 | N10: =IF($M10="완료",1,IF($M10="PM확인",0.95,IF($M10="PL확인",0.8,IF($M10="테스트",0.7,IF($M10="수행2단계",0.55,IF($M10="수행1단계",0.35,IF($M10="착수",0.2,IF($M10="미착수",0,"")))))))) -> 1
E11: 솔루션 도입 최종 검토(최종 검토 후 아래 일정 수행) | G11: 진흥원, 사업단 | I11: 46167 | J11: 46173 | K11: =IF(OR(ISBLANK($I11), ISBLANK($J11)),"",NETWORKDAYS($I11,$J11)) -> 5 | L11: =IF(OR(ISBLANK($I11), ISBLANK($J11)), "", IF('진척율보고서'!$M$4 < $I11, 0, IF('진척율보고서'!$M$4 >= $J11, 1, NETWORKDAYS($I11,'진척율보고서'!$M$4)/$K11))) -> 0 | M11: 미착수 | N11: =IF($M11="완료",1,IF($M11="PM확인",0.95,IF($M11="PL확인",0.8,IF($M11="테스트",0.7,IF($M11="수행2단계",0.55,IF($M11="수행1단계",0.35,IF($M11="착수",0.2,IF($M11="미착수",0,"")))))))) -> 0
E12: 요구사항 취합 및 정의 | G12: 사업단 | I12: 46196 | J12: 46200 | K12: =IF(OR(ISBLANK($I12), ISBLANK($J12)),"",NETWORKDAYS($I12,$J12)) -> 4 | L12: =IF(OR(ISBLANK($I12), ISBLANK($J12)), "", IF('진척율보고서'!$M$4 < $I12, 0, IF('진척율보고서'!$M$4 >= $J12, 1, NETWORKDAYS($I12,'진척율보고서'!$M$4)/$K12))) -> 0 | M12: 미착수 | N12: =IF($M12="완료",1,IF($M12="PM확인",0.95,IF($M12="PL확인",0.8,IF($M12="테스트",0.7,IF($M12="수행2단계",0.55,IF($M12="수행1단계",0.35,IF($M12="착수",0.2,IF($M12="미착수",0,"")))))))) -> 0
D13: 커스터마이징 설계
E14: 커스터마이징 범위 정의 | G14: 사업단 | I14: 46174 | J14: 46185 | K14: =IF(OR(ISBLANK($I14), ISBLANK($J14)),"",NETWORKDAYS($I14,$J14)) -> 10 | L14: =IF(OR(ISBLANK($I14), ISBLANK($J14)), "", IF('진척율보고서'!$M$4 < $I14, 0, IF('진척율보고서'!$M$4 >= $J14, 1, NETWORKDAYS($I14,'진척율보고서'!$M$4)/$K14))) -> 0 | M14: 미착수 | N14: =IF($M14="완료",1,IF($M14="PM확인",0.95,IF($M14="PL확인",0.8,IF($M14="테스트",0.7,IF($M14="수행2단계",0.55,IF($M14="수행1단계",0.35,IF($M14="착수",0.2,IF($M14="미착수",0,"")))))))) -> 0
E15: 요구사항 기능 매핑 | G15: 사업단 | I15: 46188 | J15: 46192 | K15: =IF(OR(ISBLANK($I15), ISBLANK($J15)),"",NETWORKDAYS($I15,$J15)) -> 5 | L15: =IF(OR(ISBLANK($I15), ISBLANK($J15)), "", IF('진척율보고서'!$M$4 < $I15, 0, IF('진척율보고서'!$M$4 >= $J15, 1, NETWORKDAYS($I15,'진척율보고서'!$M$4)/$K15))) -> 0 | M15: 미착수 | N15: =IF($M15="완료",1,IF($M15="PM확인",0.95,IF($M15="PL확인",0.8,IF($M15="테스트",0.7,IF($M15="수행2단계",0.55,IF($M15="수행1단계",0.35,IF($M15="착수",0.2,IF($M15="미착수",0,"")))))))) -> 0
C16: 설치 및 커스터마이징 | I16: =MIN(I17:I23) -> 46195 | J16: =MAX(J17:J23) -> 46295 | K16: =IF(OR(ISBLANK($I16), ISBLANK($J16)),"",NETWORKDAYS($I16,$J16)) -> 73 | L16: =SUM(L17:L23)/COUNT(L17:L23) -> 0 | N16: =SUM(N17:N23)/COUNT(N17:N23) -> 0
A17: ` | D17: 솔루션 설치
E18: 솔루션 설치 및 설정 | G18: 사업단 | I18: 46195 | J18: 46199 | K18: =IF(OR(ISBLANK($I18), ISBLANK($J18)),"",NETWORKDAYS($I18,$J18)) -> 5 | L18: =IF(OR(ISBLANK($I18), ISBLANK($J18)), "", IF('진척율보고서'!$M$4 < $I18, 0, IF('진척율보고서'!$M$4 >= $J18, 1, NETWORKDAYS($I18,'진척율보고서'!$M$4)/$K18))) -> 0 | M18: 미착수 | N18: =IF($M18="완료",1,IF($M18="PM확인",0.95,IF($M18="PL확인",0.8,IF($M18="테스트",0.7,IF($M18="수행2단계",0.55,IF($M18="수행1단계",0.35,IF($M18="착수",0.2,IF($M18="미착수",0,"")))))))) -> 0
E19: 솔루션 기본 기능 테스트 | G19: 사업단 | I19: 46202 | J19: 46206 | K19: =IF(OR(ISBLANK($I19), ISBLANK($J19)),"",NETWORKDAYS($I19,$J19)) -> 5 | L19: =IF(OR(ISBLANK($I19), ISBLANK($J19)), "", IF('진척율보고서'!$M$4 < $I19, 0, IF('진척율보고서'!$M$4 >= $J19, 1, NETWORKDAYS($I19,'진척율보고서'!$M$4)/$K19))) -> 0 | M19: 미착수 | N19: =IF($M19="완료",1,IF($M19="PM확인",0.95,IF($M19="PL확인",0.8,IF($M19="테스트",0.7,IF($M19="수행2단계",0.55,IF($M19="수행1단계",0.35,IF($M19="착수",0.2,IF($M19="미착수",0,"")))))))) -> 0
D20: 커스터마이징 구현
E21: 커스터마이징 대상 화면 설계 | G21: 사업단 | I21: 46209 | J21: 46234 | K21: =IF(OR(ISBLANK($I21), ISBLANK($J21)),"",NETWORKDAYS($I21,$J21)) -> 20 | L21: =IF(OR(ISBLANK($I21), ISBLANK($J21)), "", IF('진척율보고서'!$M$4 < $I21, 0, IF('진척율보고서'!$M$4 >= $J21, 1, NETWORKDAYS($I21,'진척율보고서'!$M$4)/$K21))) -> 0 | M21: 미착수 | N21: =IF($M21="완료",1,IF($M21="PM확인",0.95,IF($M21="PL확인",0.8,IF($M21="테스트",0.7,IF($M21="수행2단계",0.55,IF($M21="수행1단계",0.35,IF($M21="착수",0.2,IF($M21="미착수",0,"")))))))) -> 0
E22: 커스터마이징 대상 개발(향 후 일정 상세회 예정) | G22: 사업단 | I22: 46237 | J22: 46283 | K22: =IF(OR(ISBLANK($I22), ISBLANK($J22)),"",NETWORKDAYS($I22,$J22)) -> 35 | L22: =IF(OR(ISBLANK($I22), ISBLANK($J22)), "", IF('진척율보고서'!$M$4 < $I22, 0, IF('진척율보고서'!$M$4 >= $J22, 1, NETWORKDAYS($I22,'진척율보고서'!$M$4)/$K22))) -> 0 | M22: 미착수 | N22: =IF($M22="완료",1,IF($M22="PM확인",0.95,IF($M22="PL확인",0.8,IF($M22="테스트",0.7,IF($M22="수행2단계",0.55,IF($M22="수행1단계",0.35,IF($M22="착수",0.2,IF($M22="미착수",0,"")))))))) -> 0
E23: 솔루션 테스트 | G23: 사업단 | I23: 46286 | J23: 46295 | K23: =IF(OR(ISBLANK($I23), ISBLANK($J23)),"",NETWORKDAYS($I23,$J23)) -> 8 | L23: =IF(OR(ISBLANK($I23), ISBLANK($J23)), "", IF('진척율보고서'!$M$4 < $I23, 0, IF('진척율보고서'!$M$4 >= $J23, 1, NETWORKDAYS($I23,'진척율보고서'!$M$4)/$K23))) -> 0 | M23: 미착수 | N23: =IF($M23="완료",1,IF($M23="PM확인",0.95,IF($M23="PL확인",0.8,IF($M23="테스트",0.7,IF($M23="수행2단계",0.55,IF($M23="수행1단계",0.35,IF($M23="착수",0.2,IF($M23="미착수",0,"")))))))) -> 0
C24: 이행 | I24: =MIN(I25:I27) -> 46296 | J24: =MAX(J25:J27) -> 46311 | K24: =IF(OR(ISBLANK($I24), ISBLANK($J24)),"",NETWORKDAYS($I24,$J24)) -> 12 | L24: =SUM(L25:L27)/COUNT(L25:L27) -> 0 | N24: =SUM(N25:N27)/COUNT(N25:N27) -> 0
D25: 이행
E26: 통계솔루션 운영 매뉴얼 작성 | G26: 사업단 | I26: 46296 | J26: 46311 | K26: =IF(OR(ISBLANK($I26), ISBLANK($J26)),"",NETWORKDAYS($I26,$J26)) -> 12 | L26: =IF(OR(ISBLANK($I26), ISBLANK($J26)), "", IF('진척율보고서'!$M$4 < $I26, 0, IF('진척율보고서'!$M$4 >= $J26, 1, NETWORKDAYS($I26,'진척율보고서'!$M$4)/$K26))) -> 0 | M26: 미착수 | N26: =IF($M26="완료",1,IF($M26="PM확인",0.95,IF($M26="PL확인",0.8,IF($M26="테스트",0.7,IF($M26="수행2단계",0.55,IF($M26="수행1단계",0.35,IF($M26="착수",0.2,IF($M26="미착수",0,"")))))))) -> 0
E27: 솔루션 최종 오픈 | G27: 사업단 | I27: 46296 | J27: 46296 | K27: =IF(OR(ISBLANK($I27), ISBLANK($J27)),"",NETWORKDAYS($I27,$J27)) -> 1 | L27: =IF(OR(ISBLANK($I27), ISBLANK($J27)), "", IF('진척율보고서'!$M$4 < $I27, 0, IF('진척율보고서'!$M$4 >= $J27, 1, NETWORKDAYS($I27,'진척율보고서'!$M$4)/$K27))) -> 0 | M27: 미착수 | N27: =IF($M27="완료",1,IF($M27="PM확인",0.95,IF($M27="PL확인",0.8,IF($M27="테스트",0.7,IF($M27="수행2단계",0.55,IF($M27="수행1단계",0.35,IF($M27="착수",0.2,IF($M27="미착수",0,"")))))))) -> 0

Sheet 4.기능개선
B2: 4. 기능개선 | I2: 계획진척률(누적) | K2: =(SUM(L8:L16)+SUM(L18:L62))/(COUNT(L8:L16)+COUNT(L18:L62)) -> 0.576133 | M2: 실적진척률(누적) | O2: =(SUM(N8:N16)+SUM(N18:N62))/(COUNT(N8:N16)+COUNT(N18:N62)) -> 0.5475
I3: 계획 | M3: 실적
B4: 구분 | C4: 단계 | D4: 업무 | F4: 산출물 | G4: 담당자 | H4: 가중치 | I4: 계획시작일 | J4: 계획종료일 | K4: 기간(day) | L4: 진척률 | M4: 상태 | N4: 실적진척률 | O4: 실제시작일 | P4: 실제종료일
D5: 요약 | E5: 업무내용
B6: 고도화 및 기능개선 | H6: ='진척율보고서'!H13 -> 30 | K6: =IF(OR(ISBLANK($I6), ISBLANK($J6)),"",NETWORKDAYS($I6,$J6)) | L6: =K2*H6/100 -> 0.1728399 | N6: =O2*H6/100 -> 0.16425
C7: 기능개선 분석 및 요구사항 정의 | I7: =MIN(I8:I16) -> 46048 | J7: =MAX(J8:J16) -> 46080 | K7: =IF(OR(ISBLANK($I7), ISBLANK($J7)),"",NETWORKDAYS($I7,$J7)) -> 25 | L7: =SUM(L8:L16)/COUNT(L8:L16) -> 1 | N7: =SUM(N8:N16)/COUNT(N8:N16) -> 1
D8: 현행 시스템 분석
E9: RFP 검토 | I9: 46048 | J9: 46050 | K9: =IF(OR(ISBLANK($I9), ISBLANK($J9)),"",NETWORKDAYS($I9,$J9)) -> 3 | L9: =IF(OR(ISBLANK($I9), ISBLANK($J9)), "", IF('진척율보고서'!$M$4 < $I9, 0, IF('진척율보고서'!$M$4 >= $J9, 1, NETWORKDAYS($I9,'진척율보고서'!$M$4)/$K9))) -> 1 | M9: 완료 | N9: =IF($M9="완료",1,IF($M9="PM확인",0.95,IF($M9="PL확인",0.8,IF($M9="테스트",0.7,IF($M9="수행2단계",0.55,IF($M9="수행1단계",0.35,IF($M9="착수",0.2,IF($M9="미착수",0,"")))))))) -> 1 | O9: 46048 | P9: 46050
E10: 현행 시스템 분석 | I10: 46048 | J10: 46052 | K10: =IF(OR(ISBLANK($I10), ISBLANK($J10)),"",NETWORKDAYS($I10,$J10)) -> 5 | L10: =IF(OR(ISBLANK($I10), ISBLANK($J10)), "", IF('진척율보고서'!$M$4 < $I10, 0, IF('진척율보고서'!$M$4 >= $J10, 1, NETWORKDAYS($I10,'진척율보고서'!$M$4)/$K10))) -> 1 | M10: 완료 | N10: =IF($M10="완료",1,IF($M10="PM확인",0.95,IF($M10="PL확인",0.8,IF($M10="테스트",0.7,IF($M10="수행2단계",0.55,IF($M10="수행1단계",0.35,IF($M10="착수",0.2,IF($M10="미착수",0,"")))))))) -> 1 | O10: 46048 | P10: 46052
E11: 현행 업무프로세스 분석 | I11: 46048 | J11: 46052 | K11: =IF(OR(ISBLANK($I11), ISBLANK($J11)),"",NETWORKDAYS($I11,$J11)) -> 5 | L11: =IF(OR(ISBLANK($I11), ISBLANK($J11)), "", IF('진척율보고서'!$M$4 < $I11, 0, IF('진척율보고서'!$M$4 >= $J11, 1, NETWORKDAYS($I11,'진척율보고서'!$M$4)/$K11))) -> 1 | M11: 완료 | N11: =IF($M11="완료",1,IF($M11="PM확인",0.95,IF($M11="PL확인",0.8,IF($M11="테스트",0.7,IF($M11="수행2단계",0.55,IF($M11="수행1단계",0.35,IF($M11="착수",0.2,IF($M11="미착수",0,"")))))))) -> 1 | O11: 46048 | P11: 46052
E12: 시스템매뉴얼 분석 | I12: 46048 | J12: 46052 | K12: =IF(OR(ISBLANK($I12), ISBLANK($J12)),"",NETWORKDAYS($I12,$J12)) -> 5 | L12: =IF(OR(ISBLANK($I12), ISBLANK($J12)), "", IF('진척율보고서'!$M$4 < $I12, 0, IF('진척율보고서'!$M$4 >= $J12, 1, NETWORKDAYS($I12,'진척율보고서'!$M$4)/$K12))) -> 1 | M12: 완료 | N12: =IF($M12="완료",1,IF($M12="PM확인",0.95,IF($M12="PL확인",0.8,IF($M12="테스트",0.7,IF($M12="수행2단계",0.55,IF($M12="수행1단계",0.35,IF($M12="착수",0.2,IF($M12="미착수",0,"")))))))) -> 1 | O12: 46048 | P12: 46052
D13: 요구사항 정의
E14: 1차 요구사항 정의 | F14: 요구사항정의서 | G14: 진흥원, 사업단 | I14: 46055 | J14: 46059 | K14: =IF(OR(ISBLANK($I14), ISBLANK($J14)),"",NETWORKDAYS($I14,$J14)) -> 5 | L14: =IF(OR(ISBLANK($I14), ISBLANK($J14)), "", IF('진척율보고서'!$M$4 < $I14, 0, IF('진척율보고서'!$M$4 >= $J14, 1, NETWORKDAYS($I14,'진척율보고서'!$M$4)/$K14))) -> 1 | M14: 완료 | N14: =IF($M14="완료",1,IF($M14="PM확인",0.95,IF($M14="PL확인",0.8,IF($M14="테스트",0.7,IF($M14="수행2단계",0.55,IF($M14="수행1단계",0.35,IF($M14="착수",0.2,IF($M14="미착수",0,"")))))))) -> 1 | O14: 46055 | P14: 46059
E15: 2차 요구사항 정의 | F15: 요구사항정의서 | G15: 진흥원, 사업단 | I15: 46062 | J15: 46066 | K15: =IF(OR(ISBLANK($I15), ISBLANK($J15)),"",NETWORKDAYS($I15,$J15)) -> 5 | L15: =IF(OR(ISBLANK($I15), ISBLANK($J15)), "", IF('진척율보고서'!$M$4 < $I15, 0, IF('진척율보고서'!$M$4 >= $J15, 1, NETWORKDAYS($I15,'진척율보고서'!$M$4)/$K15))) -> 1 | M15: 완료 | N15: =IF($M15="완료",1,IF($M15="PM확인",0.95,IF($M15="PL확인",0.8,IF($M15="테스트",0.7,IF($M15="수행2단계",0.55,IF($M15="수행1단계",0.35,IF($M15="착수",0.2,IF($M15="미착수",0,"")))))))) -> 1 | O15: 46062 | P15: 46066
E16: 3차 요구사항 정의 | F16: 요구사항정의서 | G16: 진흥원, 사업단 | I16: 46076 | J16: 46080 | K16: =IF(OR(ISBLANK($I16), ISBLANK($J16)),"",NETWORKDAYS($I16,$J16)) -> 5 | L16: =IF(OR(ISBLANK($I16), ISBLANK($J16)), "", IF('진척율보고서'!$M$4 < $I16, 0, IF('진척율보고서'!$M$4 >= $J16, 1, NETWORKDAYS($I16,'진척율보고서'!$M$4)/$K16))) -> 1 | M16: 완료 | N16: =IF($M16="완료",1,IF($M16="PM확인",0.95,IF($M16="PL확인",0.8,IF($M16="테스트",0.7,IF($M16="수행2단계",0.55,IF($M16="수행1단계",0.35,IF($M16="착수",0.2,IF($M16="미착수",0,"")))))))) -> 1 | O16: 46076 | P16: 46080
C17: 기능개선 설계 및 이행 | I17: =MIN(I18:I99) -> 46057 | J17: =MAX(J18:J99) -> 46295 | K17: =IF(OR(ISBLANK($I17), ISBLANK($J17)),"",NETWORKDAYS($I17,$J17)) -> 171 | L17: =SUM(L18:L99)/COUNT(L18:L99) -> 0.29298234 | N17: =SUM(N18:N99)/COUNT(N18:N99) -> 0.26587302
A18: ` | D18: 사이트별 독립 구조 개선
E19: 가치장터 사이트 분리 대상 및 범위 분석/설계 | I19: 46057 | J19: 46066 | K19: =IF(OR(ISBLANK($I19), ISBLANK($J19)),"",NETWORKDAYS($I19,$J19)) -> 8 | L19: =IF(OR(ISBLANK($I19), ISBLANK($J19)), "", IF('진척율보고서'!$M$4 < $I19, 0, IF('진척율보고서'!$M$4 >= $J19, 1, NETWORKDAYS($I19,'진척율보고서'!$M$4)/$K19))) -> 1 | M19: 완료 | N19: =IF($M19="완료",1,IF($M19="PM확인",0.95,IF($M19="PL확인",0.8,IF($M19="테스트",0.7,IF($M19="수행2단계",0.55,IF($M19="수행1단계",0.35,IF($M19="착수",0.2,IF($M19="미착수",0,"")))))))) -> 1 | O19: 46057 | P19: 46066
E20: 가치장터 사이트 분리 대상 및 범위 개발 | I20: 46072 | J20: 46112 | K20: =IF(OR(ISBLANK($I20), ISBLANK($J20)),"",NETWORKDAYS($I20,$J20)) -> 29 | L20: =IF(OR(ISBLANK($I20), ISBLANK($J20)), "", IF('진척율보고서'!$M$4 < $I20, 0, IF('진척율보고서'!$M$4 >= $J20, 1, NETWORKDAYS($I20,'진척율보고서'!$M$4)/$K20))) -> 0.93103448 | M20: 수행2단계 | N20: =IF($M20="완료",1,IF($M20="PM확인",0.95,IF($M20="PL확인",0.8,IF($M20="테스트",0.7,IF($M20="수행2단계",0.55,IF($M20="수행1단계",0.35,IF($M20="착수",0.2,IF($M20="미착수",0,"")))))))) -> 0.55 | O20: 46072
D21: 가치장터 구매계약 UX/UI 개선
E22: UX/UI 분석 / 인터뷰
E23: 기존 업무 화면 분석 | G23: 사업단 | I23: 46072 | J23: 46094 | K23: =IF(OR(ISBLANK($I23), ISBLANK($J23)),"",NETWORKDAYS($I23,$J23)) -> 17 | L23: =IF(OR(ISBLANK($I23), ISBLANK($J23)), "", IF('진척율보고서'!$M$4 < $I23, 0, IF('진척율보고서'!$M$4 >= $J23, 1, NETWORKDAYS($I23,'진척율보고서'!$M$4)/$K23))) -> 1 | M23: 완료 | N23: =IF($M23="완료",1,IF($M23="PM확인",0.95,IF($M23="PL확인",0.8,IF($M23="테스트",0.7,IF($M23="수행2단계",0.55,IF($M23="수행1단계",0.35,IF($M23="착수",0.2,IF($M23="미착수",0,"")))))))) -> 1 | O23: 46072 | P23: 46094
A24: ` | E24: 기존 디자인 스타일 가이드 분석 | G24: 사업단 | I24: 46090 | J24: 46100 | K24: =IF(OR(ISBLANK($I24), ISBLANK($J24)),"",NETWORKDAYS($I24,$J24)) -> 9 | L24: =IF(OR(ISBLANK($I24), ISBLANK($J24)), "", IF('진척율보고서'!$M$4 < $I24, 0, IF('진척율보고서'!$M$4 >= $J24, 1, NETWORKDAYS($I24,'진척율보고서'!$M$4)/$K24))) -> 1 | M24: 완료 | N24: =IF($M24="완료",1,IF($M24="PM확인",0.95,IF($M24="PL확인",0.8,IF($M24="테스트",0.7,IF($M24="수행2단계",0.55,IF($M24="수행1단계",0.35,IF($M24="착수",0.2,IF($M24="미착수",0,"")))))))) -> 1 | O24: 46090 | P24: 46101
E25: 고객 인터뷰 시행 | G25: 진흥원, 사업단 | I25: 46101 | J25: 46101 | K25: =IF(OR(ISBLANK($I25), ISBLANK($J25)),"",NETWORKDAYS($I25,$J25)) -> 1 | L25: =IF(OR(ISBLANK($I25), ISBLANK($J25)), "", IF('진척율보고서'!$M$4 < $I25, 0, IF('진척율보고서'!$M$4 >= $J25, 1, NETWORKDAYS($I25,'진척율보고서'!$M$4)/$K25))) -> 1 | M25: 완료 | N25: =IF($M25="완료",1,IF($M25="PM확인",0.95,IF($M25="PL확인",0.8,IF($M25="테스트",0.7,IF($M25="수행2단계",0.55,IF($M25="수행1단계",0.35,IF($M25="착수",0.2,IF($M25="미착수",0,"")))))))) -> 1 | O25: 46101 | P25: 46101
E26: UX/UI 요구사항 정의 | G26: 사업단 | I26: 46104 | J26: 46112 | K26: =IF(OR(ISBLANK($I26), ISBLANK($J26)),"",NETWORKDAYS($I26,$J26)) -> 7 | L26: =IF(OR(ISBLANK($I26), ISBLANK($J26)), "", IF('진척율보고서'!$M$4 < $I26, 0, IF('진척율보고서'!$M$4 >= $J26, 1, NETWORKDAYS($I26,'진척율보고서'!$M$4)/$K26))) -> 0.71428571 | M26: 미착수 | N26: =IF($M26="완료",1,IF($M26="PM확인",0.95,IF($M26="PL확인",0.8,IF($M26="테스트",0.7,IF($M26="수행2단계",0.55,IF($M26="수행1단계",0.35,IF($M26="착수",0.2,IF($M26="미착수",0,"")))))))) -> 0
E27: UI/UX 설계 | G27: 사업단 | I27: 46112 | J27: 46130 | K27: =IF(OR(ISBLANK($I27), ISBLANK($J27)),"",NETWORKDAYS($I27,$J27)) -> 14 | L27: =IF(OR(ISBLANK($I27), ISBLANK($J27)), "", IF('진척율보고서'!$M$4 < $I27, 0, IF('진척율보고서'!$M$4 >= $J27, 1, NETWORKDAYS($I27,'진척율보고서'!$M$4)/$K27))) -> 0 | M27: 미착수 | N27: =IF($M27="완료",1,IF($M27="PM확인",0.95,IF($M27="PL확인",0.8,IF($M27="테스트",0.7,IF($M27="수행2단계",0.55,IF($M27="수행1단계",0.35,IF($M27="착수",0.2,IF($M27="미착수",0,"")))))))) -> 0
E28: UI/UX 디자인 | G28: 사업단 | I28: 46126 | J28: 46137 | K28: =IF(OR(ISBLANK($I28), ISBLANK($J28)),"",NETWORKDAYS($I28,$J28)) -> 9 | L28: =IF(OR(ISBLANK($I28), ISBLANK($J28)), "", IF('진척율보고서'!$M$4 < $I28, 0, IF('진척율보고서'!$M$4 >= $J28, 1, NETWORKDAYS($I28,'진척율보고서'!$M$4)/$K28))) -> 0 | M28: 미착수 | N28: =IF($M28="완료",1,IF($M28="PM확인",0.95,IF($M28="PL확인",0.8,IF($M28="테스트",0.7,IF($M28="수행2단계",0.55,IF($M28="수행1단계",0.35,IF($M28="착수",0.2,IF($M28="미착수",0,"")))))))) -> 0
E29: UI/UX 퍼블리싱 | G29: 사업단 | I29: 46119 | J29: 46165 | K29: =IF(OR(ISBLANK($I29), ISBLANK($J29)),"",NETWORKDAYS($I29,$J29)) -> 34 | L29: =IF(OR(ISBLANK($I29), ISBLANK($J29)), "", IF('진척율보고서'!$M$4 < $I29, 0, IF('진척율보고서'!$M$4 >= $J29, 1, NETWORKDAYS($I29,'진척율보고서'!$M$4)/$K29))) -> 0 | M29: 미착수 | N29: =IF($M29="완료",1,IF($M29="PM확인",0.95,IF($M29="PL확인",0.8,IF($M29="테스트",0.7,IF($M29="수행2단계",0.55,IF($M29="수행1단계",0.35,IF($M29="착수",0.2,IF($M29="미착수",0,"")))))))) -> 0
D30: 가치장터 구매계약 설계 / 개발
E31: 공급요청 설계/개발
E32: 공급요청 설계 | G32: 진흥원, 사업단 | I32: 46090 | J32: 46108 | K32: =IF(OR(ISBLANK($I32), ISBLANK($J32)),"",NETWORKDAYS($I32,$J32)) -> 15 | L32: =IF(OR(ISBLANK($I32), ISBLANK($J32)), "", IF('진척율보고서'!$M$4 < $I32, 0, IF('진척율보고서'!$M$4 >= $J32, 1, NETWORKDAYS($I32,'진척율보고서'!$M$4)/$K32))) -> 1 | M32: 완료 | N32: =IF($M32="완료",1,IF($M32="PM확인",0.95,IF($M32="PL확인",0.8,IF($M32="테스트",0.7,IF($M32="수행2단계",0.55,IF($M32="수행1단계",0.35,IF($M32="착수",0.2,IF($M32="미착수",0,"")))))))) -> 1 | O32: 46090 | P32: 46108
E33: 공급요청 개발 | G33: 사업단 | I33: 46111 | J33: 46115 | K33: =IF(OR(ISBLANK($I33), ISBLANK($J33)),"",NETWORKDAYS($I33,$J33)) -> 5 | L33: =IF(OR(ISBLANK($I33), ISBLANK($J33)), "", IF('진척율보고서'!$M$4 < $I33, 0, IF('진척율보고서'!$M$4 >= $J33, 1, NETWORKDAYS($I33,'진척율보고서'!$M$4)/$K33))) -> 0 | M33: 미착수 | N33: =IF($M33="완료",1,IF($M33="PM확인",0.95,IF($M33="PL확인",0.8,IF($M33="테스트",0.7,IF($M33="수행2단계",0.55,IF($M33="수행1단계",0.35,IF($M33="착수",0.2,IF($M33="미착수",0,"")))))))) -> 0
A34: ` | E34: 견적/가격협상/계약 설계/개발
E35: 견적요청 설계 | G35: 진흥원, 사업단 | I35: 46090 | J35: 46108 | K35: =IF(OR(ISBLANK($I35), ISBLANK($J35)),"",NETWORKDAYS($I35,$J35)) -> 15 | L35: =IF(OR(ISBLANK($I35), ISBLANK($J35)), "", IF('진척율보고서'!$M$4 < $I35, 0, IF('진척율보고서'!$M$4 >= $J35, 1, NETWORKDAYS($I35,'진척율보고서'!$M$4)/$K35))) -> 1 | M35: 완료 | N35: =IF($M35="완료",1,IF($M35="PM확인",0.95,IF($M35="PL확인",0.8,IF($M35="테스트",0.7,IF($M35="수행2단계",0.55,IF($M35="수행1단계",0.35,IF($M35="착수",0.2,IF($M35="미착수",0,"")))))))) -> 1 | O35: 46090 | P35: 46108
E36: 견적요청 개발 | G36: 사업단 | I36: 46118 | J36: 46122 | K36: =IF(OR(ISBLANK($I36), ISBLANK($J36)),"",NETWORKDAYS($I36,$J36)) -> 5 | L36: =IF(OR(ISBLANK($I36), ISBLANK($J36)), "", IF('진척율보고서'!$M$4 < $I36, 0, IF('진척율보고서'!$M$4 >= $J36, 1, NETWORKDAYS($I36,'진척율보고서'!$M$4)/$K36))) -> 0 | M36: 미착수 | N36: =IF($M36="완료",1,IF($M36="PM확인",0.95,IF($M36="PL확인",0.8,IF($M36="테스트",0.7,IF($M36="수행2단계",0.55,IF($M36="수행1단계",0.35,IF($M36="착수",0.2,IF($M36="미착수",0,"")))))))) -> 0
E37: 가격협상 설계 | G37: 진흥원, 사업단 | I37: 46090 | J37: 46108 | K37: =IF(OR(ISBLANK($I37), ISBLANK($J37)),"",NETWORKDAYS($I37,$J37)) -> 15 | L37: =IF(OR(ISBLANK($I37), ISBLANK($J37)), "", IF('진척율보고서'!$M$4 < $I37, 0, IF('진척율보고서'!$M$4 >= $J37, 1, NETWORKDAYS($I37,'진척율보고서'!$M$4)/$K37))) -> 1 | M37: 완료 | N37: =IF($M37="완료",1,IF($M37="PM확인",0.95,IF($M37="PL확인",0.8,IF($M37="테스트",0.7,IF($M37="수행2단계",0.55,IF($M37="수행1단계",0.35,IF($M37="착수",0.2,IF($M37="미착수",0,"")))))))) -> 1 | O37: 46090 | P37: 46108
E38: 가격협상 개발 | G38: 사업단 | I38: 46125 | J38: 46129 | K38: =IF(OR(ISBLANK($I38), ISBLANK($J38)),"",NETWORKDAYS($I38,$J38)) -> 5 | L38: =IF(OR(ISBLANK($I38), ISBLANK($J38)), "", IF('진척율보고서'!$M$4 < $I38, 0, IF('진척율보고서'!$M$4 >= $J38, 1, NETWORKDAYS($I38,'진척율보고서'!$M$4)/$K38))) -> 0 | M38: 미착수 | N38: =IF($M38="완료",1,IF($M38="PM확인",0.95,IF($M38="PL확인",0.8,IF($M38="테스트",0.7,IF($M38="수행2단계",0.55,IF($M38="수행1단계",0.35,IF($M38="착수",0.2,IF($M38="미착수",0,"")))))))) -> 0
E39: 계약대상관리 설계 | G39: 진흥원, 사업단 | I39: 46090 | J39: 46108 | K39: =IF(OR(ISBLANK($I39), ISBLANK($J39)),"",NETWORKDAYS($I39,$J39)) -> 15 | L39: =IF(OR(ISBLANK($I39), ISBLANK($J39)), "", IF('진척율보고서'!$M$4 < $I39, 0, IF('진척율보고서'!$M$4 >= $J39, 1, NETWORKDAYS($I39,'진척율보고서'!$M$4)/$K39))) -> 1 | M39: 완료 | N39: =IF($M39="완료",1,IF($M39="PM확인",0.95,IF($M39="PL확인",0.8,IF($M39="테스트",0.7,IF($M39="수행2단계",0.55,IF($M39="수행1단계",0.35,IF($M39="착수",0.2,IF($M39="미착수",0,"")))))))) -> 1 | O39: 46090 | P39: 46108
A40: ` | E40: 계약대상관리 개발 | G40: 사업단 | I40: 46132 | J40: 46136 | K40: =IF(OR(ISBLANK($I40), ISBLANK($J40)),"",NETWORKDAYS($I40,$J40)) -> 5 | L40: =IF(OR(ISBLANK($I40), ISBLANK($J40)), "", IF('진척율보고서'!$M$4 < $I40, 0, IF('진척율보고서'!$M$4 >= $J40, 1, NETWORKDAYS($I40,'진척율보고서'!$M$4)/$K40))) -> 0 | M40: 미착수 | N40: =IF($M40="완료",1,IF($M40="PM확인",0.95,IF($M40="PL확인",0.8,IF($M40="테스트",0.7,IF($M40="수행2단계",0.55,IF($M40="수행1단계",0.35,IF($M40="착수",0.2,IF($M40="미착수",0,"")))))))) -> 0
E41: 계약목록현황 설계 | G41: 진흥원, 사업단 | I41: 46090 | J41: 46108 | K41: =IF(OR(ISBLANK($I41), ISBLANK($J41)),"",NETWORKDAYS($I41,$J41)) -> 15 | L41: =IF(OR(ISBLANK($I41), ISBLANK($J41)), "", IF('진척율보고서'!$M$4 < $I41, 0, IF('진척율보고서'!$M$4 >= $J41, 1, NETWORKDAYS($I41,'진척율보고서'!$M$4)/$K41))) -> 1 | M41: 완료 | N41: =IF($M41="완료",1,IF($M41="PM확인",0.95,IF($M41="PL확인",0.8,IF($M41="테스트",0.7,IF($M41="수행2단계",0.55,IF($M41="수행1단계",0.35,IF($M41="착수",0.2,IF($M41="미착수",0,"")))))))) -> 1 | O41: 46090 | P41: 46108
...

Sheet 5.SLA협약
B2: 6. SLA협약 | I2: 계획진척률(누적) | K2: =(SUM(L8:L23)/(COUNT(L8:L23))) -> 0.375 | M2: 실적진척률(누적) | O2: =(SUM(N8:N23)/(COUNT(N8:N23))) -> 0.37916667
I3: 계획 | M3: 실적
B4: 구분 | C4: 단계 | D4: 업무 | F4: 산출물 | G4: 담당자 | H4: 가중치 | I4: 계획시작일 | J4: 계획종료일 | K4: 기간(day) | L4: 진척률 | M4: 상태 | N4: 실적진척률 | O4: 실제시작일 | P4: 실제종료일
D5: 요약 | E5: 업무내용
B6: 판로플랫폼 유지보수 | H6: ='진척율보고서'!H14 -> 20 | K6: =IF(OR(ISBLANK($I6), ISBLANK($J6)),"",NETWORKDAYS($I6,$J6)) | L6: =K2*H6/100 -> 0.075 | N6: =O2*H6/100 -> 0.075833333
C7: SLA협약 | I7: =MIN(I8:I23) -> 46076 | J7: =MAX(J8:J23) -> 46204 | K7: =IF(OR(ISBLANK($I7), ISBLANK($J7)),"",NETWORKDAYS($I7,$J7)) -> 93 | L7: =SUM(L8:L23)/COUNT(L8:L23) -> 0.375 | N7: =SUM(N8:N23)/COUNT(N8:N23) -> 0.37916667
D8: 분석
E9: 타기관 SLA 지표 분석 | F9: SLA_협약서_비교분석_보고서 | I9: 46076 | J9: 46080 | K9: =IF(OR(ISBLANK($I9), ISBLANK($J9)),"",NETWORKDAYS($I9,$J9)) -> 5 | L9: =IF(OR(ISBLANK($I9), ISBLANK($J9)), "", IF('진척율보고서'!$M$4 < $I9, 0, IF('진척율보고서'!$M$4 >= $J9, 1, NETWORKDAYS($I9,'진척율보고서'!$M$4)/$K9))) -> 1 | M9: 완료 | N9: =IF($M9="완료",1,IF($M9="PM확인",0.95,IF($M9="PL확인",0.8,IF($M9="테스트",0.7,IF($M9="수행2단계",0.55,IF($M9="수행1단계",0.35,IF($M9="착수",0.2,IF($M9="미착수",0,"")))))))) -> 1
E10: SLA 목표 수준 정의 | F10: SLA_협약서_비교분석_보고서 | I10: 46076 | J10: 46080 | K10: =IF(OR(ISBLANK($I10), ISBLANK($J10)),"",NETWORKDAYS($I10,$J10)) -> 5 | L10: =IF(OR(ISBLANK($I10), ISBLANK($J10)), "", IF('진척율보고서'!$M$4 < $I10, 0, IF('진척율보고서'!$M$4 >= $J10, 1, NETWORKDAYS($I10,'진척율보고서'!$M$4)/$K10))) -> 1 | M10: 완료 | N10: =IF($M10="완료",1,IF($M10="PM확인",0.95,IF($M10="PL확인",0.8,IF($M10="테스트",0.7,IF($M10="수행2단계",0.55,IF($M10="수행1단계",0.35,IF($M10="착수",0.2,IF($M10="미착수",0,"")))))))) -> 1
D11: 지표 도출
E12: 서비스 평가 항목 및 가중치 도출 | F12: SLA협약서(초안) | G12: 진흥원, 사업단 | I12: 46084 | J12: 46094 | K12: =IF(OR(ISBLANK($I12), ISBLANK($J12)),"",NETWORKDAYS($I12,$J12)) -> 9 | L12: =IF(OR(ISBLANK($I12), ISBLANK($J12)), "", IF('진척율보고서'!$M$4 < $I12, 0, IF('진척율보고서'!$M$4 >= $J12, 1, NETWORKDAYS($I12,'진척율보고서'!$M$4)/$K12))) -> 1 | M12: 완료 | N12: =IF($M12="완료",1,IF($M12="PM확인",0.95,IF($M12="PL확인",0.8,IF($M12="테스트",0.7,IF($M12="수행2단계",0.55,IF($M12="수행1단계",0.35,IF($M12="착수",0.2,IF($M12="미착수",0,"")))))))) -> 1
E13: 서비스 수준 평가 등급 도출 | F13: SLA협약서(초안) | G13: 진흥원, 사업단 | I13: 46097 | J13: 46101 | K13: =IF(OR(ISBLANK($I13), ISBLANK($J13)),"",NETWORKDAYS($I13,$J13)) -> 5 | L13: =IF(OR(ISBLANK($I13), ISBLANK($J13)), "", IF('진척율보고서'!$M$4 < $I13, 0, IF('진척율보고서'!$M$4 >= $J13, 1, NETWORKDAYS($I13,'진척율보고서'!$M$4)/$K13))) -> 1 | M13: 완료 | N13: =IF($M13="완료",1,IF($M13="PM확인",0.95,IF($M13="PL확인",0.8,IF($M13="테스트",0.7,IF($M13="수행2단계",0.55,IF($M13="수행1단계",0.35,IF($M13="착수",0.2,IF($M13="미착수",0,"")))))))) -> 1
E14: 서비스 평가항목별 지표 도출 | F14: SLA협약서(초안) | G14: 진흥원, 사업단 | I14: 46104 | J14: 46115 | K14: =IF(OR(ISBLANK($I14), ISBLANK($J14)),"",NETWORKDAYS($I14,$J14)) -> 10 | L14: =IF(OR(ISBLANK($I14), ISBLANK($J14)), "", IF('진척율보고서'!$M$4 < $I14, 0, IF('진척율보고서'!$M$4 >= $J14, 1, NETWORKDAYS($I14,'진척율보고서'!$M$4)/$K14))) -> 0.5 | M14: 수행2단계 | N14: =IF($M14="완료",1,IF($M14="PM확인",0.95,IF($M14="PL확인",0.8,IF($M14="테스트",0.7,IF($M14="수행2단계",0.55,IF($M14="수행1단계",0.35,IF($M14="착수",0.2,IF($M14="미착수",0,"")))))))) -> 0.55
E15: SLA 평가 처리 문서 개발 | F15: SLA협약서(초안) | G15: 진흥원, 사업단 | I15: 46118 | J15: 46129 | K15: =IF(OR(ISBLANK($I15), ISBLANK($J15)),"",NETWORKDAYS($I15,$J15)) -> 10 | L15: =IF(OR(ISBLANK($I15), ISBLANK($J15)), "", IF('진척율보고서'!$M$4 < $I15, 0, IF('진척율보고서'!$M$4 >= $J15, 1, NETWORKDAYS($I15,'진척율보고서'!$M$4)/$K15))) -> 0 | M15: 미착수 | N15: =IF($M15="완료",1,IF($M15="PM확인",0.95,IF($M15="PL확인",0.8,IF($M15="테스트",0.7,IF($M15="수행2단계",0.55,IF($M15="수행1단계",0.35,IF($M15="착수",0.2,IF($M15="미착수",0,"")))))))) -> 0
E16: 서비스 평가 항목 및 지표 확정 | F16: SLA협약서(초안) | G16: 진흥원, 사업단 | I16: 46132 | J16: 46136 | K16: =IF(OR(ISBLANK($I16), ISBLANK($J16)),"",NETWORKDAYS($I16,$J16)) -> 5 | L16: =IF(OR(ISBLANK($I16), ISBLANK($J16)), "", IF('진척율보고서'!$M$4 < $I16, 0, IF('진척율보고서'!$M$4 >= $J16, 1, NETWORKDAYS($I16,'진척율보고서'!$M$4)/$K16))) -> 0 | M16: 미착수 | N16: =IF($M16="완료",1,IF($M16="PM확인",0.95,IF($M16="PL확인",0.8,IF($M16="테스트",0.7,IF($M16="수행2단계",0.55,IF($M16="수행1단계",0.35,IF($M16="착수",0.2,IF($M16="미착수",0,"")))))))) -> 0
D17: 시범운영
E18: 시범운영 | I18: 46143 | J18: 46171 | K18: =IF(OR(ISBLANK($I18), ISBLANK($J18)),"",NETWORKDAYS($I18,$J18)) -> 21 | L18: =IF(OR(ISBLANK($I18), ISBLANK($J18)), "", IF('진척율보고서'!$M$4 < $I18, 0, IF('진척율보고서'!$M$4 >= $J18, 1, NETWORKDAYS($I18,'진척율보고서'!$M$4)/$K18))) -> 0 | M18: 미착수 | N18: =IF($M18="완료",1,IF($M18="PM확인",0.95,IF($M18="PL확인",0.8,IF($M18="테스트",0.7,IF($M18="수행2단계",0.55,IF($M18="수행1단계",0.35,IF($M18="착수",0.2,IF($M18="미착수",0,"")))))))) -> 0
E19: 시범운영 결과 분석 | I19: 46174 | J19: 46178 | K19: =IF(OR(ISBLANK($I19), ISBLANK($J19)),"",NETWORKDAYS($I19,$J19)) -> 5 | L19: =IF(OR(ISBLANK($I19), ISBLANK($J19)), "", IF('진척율보고서'!$M$4 < $I19, 0, IF('진척율보고서'!$M$4 >= $J19, 1, NETWORKDAYS($I19,'진척율보고서'!$M$4)/$K19))) -> 0 | M19: 미착수 | N19: =IF($M19="완료",1,IF($M19="PM확인",0.95,IF($M19="PL확인",0.8,IF($M19="테스트",0.7,IF($M19="수행2단계",0.55,IF($M19="수행1단계",0.35,IF($M19="착수",0.2,IF($M19="미착수",0,"")))))))) -> 0
E20: 시범운영 결과 보고 | I20: 46181 | J20: 46185 | K20: =IF(OR(ISBLANK($I20), ISBLANK($J20)),"",NETWORKDAYS($I20,$J20)) -> 5 | L20: =IF(OR(ISBLANK($I20), ISBLANK($J20)), "", IF('진척율보고서'!$M$4 < $I20, 0, IF('진척율보고서'!$M$4 >= $J20, 1, NETWORKDAYS($I20,'진척율보고서'!$M$4)/$K20))) -> 0 | M20: 미착수 | N20: =IF($M20="완료",1,IF($M20="PM확인",0.95,IF($M20="PL확인",0.8,IF($M20="테스트",0.7,IF($M20="수행2단계",0.55,IF($M20="수행1단계",0.35,IF($M20="착수",0.2,IF($M20="미착수",0,"")))))))) -> 0
D21: 확정
E22: SLA 최종 확정 | F22: SLA협약서(최종)) | G22: 진흥원, 사업단 | I22: 46188 | J22: 46192 | K22: =IF(OR(ISBLANK($I22), ISBLANK($J22)),"",NETWORKDAYS($I22,$J22)) -> 5 | L22: =IF(OR(ISBLANK($I22), ISBLANK($J22)), "", IF('진척율보고서'!$M$4 < $I22, 0, IF('진척율보고서'!$M$4 >= $J22, 1, NETWORKDAYS($I22,'진척율보고서'!$M$4)/$K22))) -> 0 | M22: 미착수 | N22: =IF($M22="완료",1,IF($M22="PM확인",0.95,IF($M22="PL확인",0.8,IF($M22="테스트",0.7,IF($M22="수행2단계",0.55,IF($M22="수행1단계",0.35,IF($M22="착수",0.2,IF($M22="미착수",0,"")))))))) -> 0
E23: SLA 적용 | F23: 월간보고서(7월말) | I23: 46204 | J23: 46204 | K23: =IF(OR(ISBLANK($I23), ISBLANK($J23)),"",NETWORKDAYS($I23,$J23)) -> 1 | L23: =IF(OR(ISBLANK($I23), ISBLANK($J23)), "", IF('진척율보고서'!$M$4 < $I23, 0, IF('진척율보고서'!$M$4 >= $J23, 1, NETWORKDAYS($I23,'진척율보고서'!$M$4)/$K23))) -> 0 | M23: 미착수 | N23: =IF($M23="완료",1,IF($M23="PM확인",0.95,IF($M23="PL확인",0.8,IF($M23="테스트",0.7,IF($M23="수행2단계",0.55,IF($M23="수행1단계",0.35,IF($M23="착수",0.2,IF($M23="미착수",0,"")))))))) -> 0

Sheet (중요) 업무요청시트(260223)
A1: ㅇ 작성 유의사항 -> 개발 필요사항 등 어드민 페이지에서 작성하기 어려운 내용만 해당 시트로 요청 예정, 그 외 사항은 어드민 페이지에서 요청입력 예정 - 현재시트 외 각 카테고리별로 각 시트별 예시를 참고하여 담당자별 프로젝트 관리사항 입력 관리 요청 - 해당 자료를 기반으로, 주간 보고, 월간 보고 등 활용 예정 | K1: ※ 주간 또는 월간 회의 매주 15시 2.24.(화) 15시 * 참석자: 진흥원 김영규 팀장, 황병준 과장 * 요청사항: 줌 개설 후 회의 참가 링크 공유 요청
A2: 2026년 판로플랫폼 고도화 및 유지관리 용역 업무관리시트(관리용) | K2: 필요 시 작성 | L2: 필요 시 작성 | M2: 필요 시 작성 | N2: 필요 시 작성 | O2: 필요 시 작성
A3: 연번 | B3: 구분 | C3: 우선순위 | D3: 상태 | E3: 요청일 | F3: 완료 희망일 | G3: 완료일 | H3: 요청자 (진흥원 담당) | I3: 처리 담당자 (수행사) | J3: 요청사항 (진흥원->수행사) | K3: 요청 사항 (수행사->진흥원) | L3: 조치사항 (진흥원) | M3: 조치사항 (수행사) | N3: 처리 결과 (진흥원) | O3: 처리 결과 (수행사)
A4: 1 | B4: 1. 사업관리 | C4: 보통 | D4: 완료 | E4: 46045 | F4: 46045 | G4: 46045 | H4: 황병준 | I4: 김선형 | J4: 페이지 로딩속도 반응 느림 및 불안정 | K4: 클라우드 서버 증량 필요 | L4: 필요 내역(메모리 증설 등) 회신 요청 | M4: 필요 내역(메모리 증설 등) 회신 완료 | N4: 진흥원 정보화팀 요청 완료(3~4일 소요 에정) | O4: 1/21(목) 18:00 ~ 19:10 WAS1,2서버 메모리 증설 완료
A5: 2 | B5: 2. 챗봇 | C5: 보통 | D5: 완료 | E5: 46045 | F5: 46058 | G5: 46058 | H5: 황병준 | I5: 송현주 | J5: 간편인증 화면 개선
A6: 3 | B6: 2. 챗봇 | C6: 긴급 | D6: 완료 | E6: 46045 | F6: 46098 | G6: 46098 | H6: 황병준 | J6: 챗봇, 티켓관리 솔루션 나라장터 입점 여부 및 구매 가능 여부 확인(구매 가능 예산 최대 55백만원) | N6: 챗봇(자산), 그외(클라우드 서비스 이용) | O6: 확인 후 메일 회신 완료
A7: 4 | B7: 4. 기능개선 | C7: 보통 | D7: 완료 | E7: 46044 | F7: 46044 | G7: 46044 | H7: 황병준 | I7: 황안나 | J7: 어드민 관리자 계정 생성 (ID) socialover | O7: 1/22 메일로 관련 내용 전달
A8: 5 | B8: 4. 기능개선 | C8: 보통 | D8: 완료 | E8: 46044 | F8: 46044 | G8: 46044 | H8: 황병준 | I8: 황안나 | J8: 어드민 페이지 등 정보접근 권한 관련 관계자 ID 및 이름 목록 요청 | O8: 1/22 메일로 관련 내용 전달
A9: 6 | B9: 1. 사업관리 | C9: 높음 | E9: 46048 | F9: 46059 | H9: 황병준 | I9: 장일훈 | J9: 2025년 유지관리 용역 개인정보 파기 공문 회신 요청
A10: 7 | B10: 1. 사업관리 | C10: 높음 | D10: 완료 | E10: 46050 | F10: 46063 | G10: 46063 | H10: 황병준 | I10: 장일훈 | J10: 착수보고회 일정('26.2.10.(화) 14:00~16:00(예정), 진흥원 7층 영상회의실 | L10: 장소 변경(서울->성남) | M10: 참여인력 파악 및 출력물 준비 필요
A11: 8 | B11: 1. 사업관리 | C11: 긴급 | D11: 완료 | E11: 46051 | F11: 46052 | G11: 46052 | H11: 신이수 | I11: 황안나 | J11: 어드민 관리자 계정 생성 (ID) 1sshin | O11: 1/30 메일로 관련 내용 전달
A12: 9 | B12: 1. 사업관리 | C12: 낮음 | D12: 완료 | E12: 46055 | F12: 46056 | G12: 46056 | H12: 황병준 | I12: 황안나 | J12: 주간회의 줌링크 생성 및 공유(2.3.(화) 15:00) | O12: 2/3 메일로 줌정보 전달
A13: 10 | B13: 1. 사업관리 | C13: 긴급 | D13: 완료 | E13: 46056 | F13: 46057 | G13: 46057 | H13: 황병준 | I13: 김선형 | J13: 시스템 오류사항(강원도 등) 접근 차단 원인 포함 보고서 제출 요청 | O13: 2/4 메일 전달(제목 : [502에러] 횡성군청 가치장터 접속에러 조치 내용)
A14: 11 | B14: 1. 사업관리 | C14: 보통 | D14: 완료 | E14: 46056 | F14: 46056 | G14: 46056 | H14: 황병준 | I14: 김선형 | J14: 클라우드 서버 증량 등 요청사항 정리 및 송부 요청 | O14: 2/3 메일 전달-첨부파일내용기입(제목 : [RE][한국사회적기업진흥원] [판로지원팀] 시스템 장애 조치 보고서 작성 양식 송부 및 회신 요청)
A15: 12 | B15: 1. 사업관리 | C15: 긴급 | D15: 완료 | E15: 46057 | F15: 46057 | G15: 46057 | H15: 황병준 | I15: 김선형 | J15: 방화벽 솔루션 재설치 내역(설치일자 등 포함) 관련 메일 전달 요청 | O15: 2/4 메일 전달(제목 : [FW][한국사회적기업진흥원] 판로서비스 웹방화벽(WAF) 변경에 따른 환경 설정 완료 및 테스트 요청의 건 [FW][한국사회적기업진흥원] 웹방화벽(WAF) 도입/변경에 따른 DNS 변경 요청 건)
A16: 13 | B16: 1. 사업관리 | C16: 보통 | D16: 완료 | E16: 46058 | F16: 46065 | G16: 46064 | H16: 황병준 | I16: 황안나 | J16: 정보접근권한 신청서 및 보안서약서 제출(투입인력 전원)_메일 송부 예정 | O16: 2/11 메일로 관련 내용 전달
A17: 14 | B17: 1. 사업관리 | C17: 높음 | D17: 완료 | E17: 46062 | F17: 46065 | G17: 46065 | H17: 황병준 | I17: 김선형 | J17: 엑셀리언트_구글애널리틱스4, 가치장터&스토어36.5 현재 적용 소스 코드 요청 | O17: 2/12 관련요청자료 메일로 전달
A18: 15 | B18: 4. 기능개선 | C18: 보통 | E18: 46063 | H18: 황병준 | J18: 검색엔진(와이즈넛) 검색 필터 변경 요청(기존 OR 조건 변경 AND 조건), 필요 시, 견적 요청 등 진행 부탁(와이즈넛)
A19: 16 | B19: 1. 사업관리 | C19: 긴급 | D19: 완료 | E19: 46073 | F19: 46077 | G19: 46077 | H19: 황병준 | I19: 황안나 | J19: 스토어 입점사 -> 사회적경제기업(사회적기업, 사회적협동조합, 창업기업 선택 후) 테스트 계정 생성 (ID) Test00015 | L19: (사유) 오엠 개인 계정으로 원래 테스트 계정 아님 | O19: 2/24 테스트계정 로그인계정 (tests2018) 메일로 전달
A20: 17 | B20: 1. 사업관리 | C20: 긴급 | D20: 완료 | E20: 46073 | F20: 46076 | G20: 46076 | H20: 황병준 | I20: 황안나 | J20: 가치장터-나라장터 연계(조달청 공고요청) 기관코드 일치 불일치 현황 점검(현황파악 요청) | O20: 2/23 행정표준기관코드와 비교 자료 메일로 전달
A21: 18 | B21: 1. 사업관리 | C21: 높음 | D21: 완료 | E21: 46073 | F21: 46098 | G21: 46098 | H21: 황병준 | J21: 가치장터-나라장터 조달청 공고요청 송신 후 나라장터 화면 확인 방법 확인 요청 | N21: 확인 완료, 화면 설계 변경 필요
A22: 19 | B22: 1. 사업관리 | C22: 긴급 | D22: 완료 | E22: 46076 | F22: 0202-02-25 | G22: 0202-02-25 | H22: 황병준 | I22: 황안나 | J22: 판로플랫폼 행정표준코드(대전, 충남, 광주, 전남, 대구, 경북) 연계 데이터 현황조사 | O22: 2/25 메일로 관련 파일 전달

Sheet (TODO) 서비스데스크 업무 관리
A1: ㅇ 작성범위 - 서비스데스크 및 추가 요건 사항에 대해 작성 및 관리
A2: 2026년 서비스데스크 업무 관리 시트
A3: No | B3: 출처 | C3: 요청자구분 | D3: 요청자 | E3: 요청일자 | F3: 요청사항 | G3: 협의내용 (회의 후 작성) | H3: 진행상태 | I3: 처리담당자 | J3: 처리예정일자 | K3: 처리완료일자 | L3: 처리결과 (시스템 반영 후 작성)
A4: 1 | B4: 서비스데스크 (1323) | C4: 진흥원 | D4: 이혜정 | E4: 46030 | F4: 가치장터 '기업정보 조회' 검색항목 추가, 수정 | G4: < 26-01-27 협의 > - 화면명 변경 - 검색조건 추가 및 순서변경 : 우선구매대상, 지역, 가격범위, 기업명(추가), 사업자등록번호, 사회적가치지표전체, 탁월, 우수)(추가) < 26-01-28 협의 > - (보류) 사회적가치지표 추가(추후 논의) | H4: 보류 | I4: 황안나 | J4: 46051 | K4: 46051 | L4: < 26-01-29 > 검색 항목(기업명) 추가 및 순서변경하여 반영함
